[2024-04-13T05:46:04.182+0000] {processor.py:161} INFO - Started process (PID=1770) to work on /opt/airflow/dags/verdemar_etl.py
[2024-04-13T05:46:04.182+0000] {processor.py:830} INFO - Processing file /opt/airflow/dags/verdemar_etl.py for tasks to queue
[2024-04-13T05:46:04.184+0000] {logging_mixin.py:188} INFO - [2024-04-13T05:46:04.183+0000] {dagbag.py:540} INFO - Filling up the DagBag from /opt/airflow/dags/verdemar_etl.py
[2024-04-13T05:46:04.419+0000] {logging_mixin.py:188} INFO - [2024-04-13T05:46:04.416+0000] {dagbag.py:350} ERROR - Failed to import: /opt/airflow/dags/verdemar_etl.py
Traceback (most recent call last):
  File "/home/airflow/.local/lib/python3.12/site-packages/airflow/models/dagbag.py", line 346, in parse
    loader.exec_module(new_module)
  File "<frozen importlib._bootstrap_external>", line 995, in exec_module
  File "<frozen importlib._bootstrap>", line 488, in _call_with_frames_removed
  File "/opt/airflow/dags/verdemar_etl.py", line 4, in <module>
    from astro import sql as aql
ModuleNotFoundError: No module named 'astro'
[2024-04-13T05:46:04.420+0000] {processor.py:842} WARNING - No viable dags retrieved from /opt/airflow/dags/verdemar_etl.py
[2024-04-13T05:46:04.439+0000] {processor.py:183} INFO - Processing /opt/airflow/dags/verdemar_etl.py took 0.261 seconds
[2024-04-13T05:46:34.922+0000] {processor.py:161} INFO - Started process (PID=1830) to work on /opt/airflow/dags/verdemar_etl.py
[2024-04-13T05:46:34.923+0000] {processor.py:830} INFO - Processing file /opt/airflow/dags/verdemar_etl.py for tasks to queue
[2024-04-13T05:46:34.925+0000] {logging_mixin.py:188} INFO - [2024-04-13T05:46:34.924+0000] {dagbag.py:540} INFO - Filling up the DagBag from /opt/airflow/dags/verdemar_etl.py
[2024-04-13T05:46:35.068+0000] {logging_mixin.py:188} INFO - [2024-04-13T05:46:35.067+0000] {dagbag.py:350} ERROR - Failed to import: /opt/airflow/dags/verdemar_etl.py
Traceback (most recent call last):
  File "/home/airflow/.local/lib/python3.12/site-packages/airflow/models/dagbag.py", line 346, in parse
    loader.exec_module(new_module)
  File "<frozen importlib._bootstrap_external>", line 995, in exec_module
  File "<frozen importlib._bootstrap>", line 488, in _call_with_frames_removed
  File "/opt/airflow/dags/verdemar_etl.py", line 4, in <module>
    from astro import sql as aql
ModuleNotFoundError: No module named 'astro'
[2024-04-13T05:46:35.068+0000] {processor.py:842} WARNING - No viable dags retrieved from /opt/airflow/dags/verdemar_etl.py
[2024-04-13T05:46:35.078+0000] {processor.py:183} INFO - Processing /opt/airflow/dags/verdemar_etl.py took 0.175 seconds
[2024-04-13T05:47:05.282+0000] {processor.py:161} INFO - Started process (PID=1890) to work on /opt/airflow/dags/verdemar_etl.py
[2024-04-13T05:47:05.283+0000] {processor.py:830} INFO - Processing file /opt/airflow/dags/verdemar_etl.py for tasks to queue
[2024-04-13T05:47:05.285+0000] {logging_mixin.py:188} INFO - [2024-04-13T05:47:05.284+0000] {dagbag.py:540} INFO - Filling up the DagBag from /opt/airflow/dags/verdemar_etl.py
[2024-04-13T05:47:05.419+0000] {logging_mixin.py:188} INFO - [2024-04-13T05:47:05.418+0000] {dagbag.py:350} ERROR - Failed to import: /opt/airflow/dags/verdemar_etl.py
Traceback (most recent call last):
  File "/home/airflow/.local/lib/python3.12/site-packages/airflow/models/dagbag.py", line 346, in parse
    loader.exec_module(new_module)
  File "<frozen importlib._bootstrap_external>", line 995, in exec_module
  File "<frozen importlib._bootstrap>", line 488, in _call_with_frames_removed
  File "/opt/airflow/dags/verdemar_etl.py", line 4, in <module>
    from astro import sql as aql
ModuleNotFoundError: No module named 'astro'
[2024-04-13T05:47:05.420+0000] {processor.py:842} WARNING - No viable dags retrieved from /opt/airflow/dags/verdemar_etl.py
[2024-04-13T05:47:05.430+0000] {processor.py:183} INFO - Processing /opt/airflow/dags/verdemar_etl.py took 0.152 seconds
[2024-04-13T05:47:35.458+0000] {processor.py:161} INFO - Started process (PID=1949) to work on /opt/airflow/dags/verdemar_etl.py
[2024-04-13T05:47:35.459+0000] {processor.py:830} INFO - Processing file /opt/airflow/dags/verdemar_etl.py for tasks to queue
[2024-04-13T05:47:35.461+0000] {logging_mixin.py:188} INFO - [2024-04-13T05:47:35.461+0000] {dagbag.py:540} INFO - Filling up the DagBag from /opt/airflow/dags/verdemar_etl.py
[2024-04-13T05:47:35.730+0000] {logging_mixin.py:188} INFO - [2024-04-13T05:47:35.728+0000] {dagbag.py:350} ERROR - Failed to import: /opt/airflow/dags/verdemar_etl.py
Traceback (most recent call last):
  File "/home/airflow/.local/lib/python3.12/site-packages/airflow/models/dagbag.py", line 346, in parse
    loader.exec_module(new_module)
  File "<frozen importlib._bootstrap_external>", line 995, in exec_module
  File "<frozen importlib._bootstrap>", line 488, in _call_with_frames_removed
  File "/opt/airflow/dags/verdemar_etl.py", line 4, in <module>
    from astro import sql as aql
ModuleNotFoundError: No module named 'astro'
[2024-04-13T05:47:35.731+0000] {processor.py:842} WARNING - No viable dags retrieved from /opt/airflow/dags/verdemar_etl.py
[2024-04-13T05:47:35.748+0000] {processor.py:183} INFO - Processing /opt/airflow/dags/verdemar_etl.py took 0.298 seconds
[2024-04-13T05:48:06.820+0000] {processor.py:161} INFO - Started process (PID=2008) to work on /opt/airflow/dags/verdemar_etl.py
[2024-04-13T05:48:06.821+0000] {processor.py:830} INFO - Processing file /opt/airflow/dags/verdemar_etl.py for tasks to queue
[2024-04-13T05:48:06.834+0000] {logging_mixin.py:188} INFO - [2024-04-13T05:48:06.831+0000] {dagbag.py:540} INFO - Filling up the DagBag from /opt/airflow/dags/verdemar_etl.py
[2024-04-13T05:48:07.116+0000] {logging_mixin.py:188} INFO - [2024-04-13T05:48:07.114+0000] {dagbag.py:350} ERROR - Failed to import: /opt/airflow/dags/verdemar_etl.py
Traceback (most recent call last):
  File "/home/airflow/.local/lib/python3.12/site-packages/airflow/models/dagbag.py", line 346, in parse
    loader.exec_module(new_module)
  File "<frozen importlib._bootstrap_external>", line 995, in exec_module
  File "<frozen importlib._bootstrap>", line 488, in _call_with_frames_removed
  File "/opt/airflow/dags/verdemar_etl.py", line 4, in <module>
    from astro import sql as aql
ModuleNotFoundError: No module named 'astro'
[2024-04-13T05:48:07.117+0000] {processor.py:842} WARNING - No viable dags retrieved from /opt/airflow/dags/verdemar_etl.py
[2024-04-13T05:48:07.140+0000] {processor.py:183} INFO - Processing /opt/airflow/dags/verdemar_etl.py took 0.329 seconds
[2024-04-13T05:48:37.419+0000] {processor.py:161} INFO - Started process (PID=2068) to work on /opt/airflow/dags/verdemar_etl.py
[2024-04-13T05:48:37.421+0000] {processor.py:830} INFO - Processing file /opt/airflow/dags/verdemar_etl.py for tasks to queue
[2024-04-13T05:48:37.426+0000] {logging_mixin.py:188} INFO - [2024-04-13T05:48:37.425+0000] {dagbag.py:540} INFO - Filling up the DagBag from /opt/airflow/dags/verdemar_etl.py
[2024-04-13T05:48:37.792+0000] {logging_mixin.py:188} INFO - [2024-04-13T05:48:37.790+0000] {dagbag.py:350} ERROR - Failed to import: /opt/airflow/dags/verdemar_etl.py
Traceback (most recent call last):
  File "/home/airflow/.local/lib/python3.12/site-packages/airflow/models/dagbag.py", line 346, in parse
    loader.exec_module(new_module)
  File "<frozen importlib._bootstrap_external>", line 995, in exec_module
  File "<frozen importlib._bootstrap>", line 488, in _call_with_frames_removed
  File "/opt/airflow/dags/verdemar_etl.py", line 4, in <module>
    from astro import sql as aql
ModuleNotFoundError: No module named 'astro'
[2024-04-13T05:48:37.792+0000] {processor.py:842} WARNING - No viable dags retrieved from /opt/airflow/dags/verdemar_etl.py
[2024-04-13T05:48:37.814+0000] {processor.py:183} INFO - Processing /opt/airflow/dags/verdemar_etl.py took 0.409 seconds
[2024-04-13T05:49:08.446+0000] {processor.py:161} INFO - Started process (PID=2128) to work on /opt/airflow/dags/verdemar_etl.py
[2024-04-13T05:49:08.448+0000] {processor.py:830} INFO - Processing file /opt/airflow/dags/verdemar_etl.py for tasks to queue
[2024-04-13T05:49:08.453+0000] {logging_mixin.py:188} INFO - [2024-04-13T05:49:08.452+0000] {dagbag.py:540} INFO - Filling up the DagBag from /opt/airflow/dags/verdemar_etl.py
[2024-04-13T05:49:08.764+0000] {logging_mixin.py:188} INFO - [2024-04-13T05:49:08.762+0000] {dagbag.py:350} ERROR - Failed to import: /opt/airflow/dags/verdemar_etl.py
Traceback (most recent call last):
  File "/home/airflow/.local/lib/python3.12/site-packages/airflow/models/dagbag.py", line 346, in parse
    loader.exec_module(new_module)
  File "<frozen importlib._bootstrap_external>", line 995, in exec_module
  File "<frozen importlib._bootstrap>", line 488, in _call_with_frames_removed
  File "/opt/airflow/dags/verdemar_etl.py", line 4, in <module>
    from astro import sql as aql
ModuleNotFoundError: No module named 'astro'
[2024-04-13T05:49:08.764+0000] {processor.py:842} WARNING - No viable dags retrieved from /opt/airflow/dags/verdemar_etl.py
[2024-04-13T05:49:08.783+0000] {processor.py:183} INFO - Processing /opt/airflow/dags/verdemar_etl.py took 0.356 seconds
[2024-04-13T05:49:39.250+0000] {processor.py:161} INFO - Started process (PID=2188) to work on /opt/airflow/dags/verdemar_etl.py
[2024-04-13T05:49:39.253+0000] {processor.py:830} INFO - Processing file /opt/airflow/dags/verdemar_etl.py for tasks to queue
[2024-04-13T05:49:39.260+0000] {logging_mixin.py:188} INFO - [2024-04-13T05:49:39.259+0000] {dagbag.py:540} INFO - Filling up the DagBag from /opt/airflow/dags/verdemar_etl.py
[2024-04-13T05:49:39.512+0000] {logging_mixin.py:188} INFO - [2024-04-13T05:49:39.504+0000] {dagbag.py:350} ERROR - Failed to import: /opt/airflow/dags/verdemar_etl.py
Traceback (most recent call last):
  File "/home/airflow/.local/lib/python3.12/site-packages/airflow/models/dagbag.py", line 346, in parse
    loader.exec_module(new_module)
  File "<frozen importlib._bootstrap_external>", line 995, in exec_module
  File "<frozen importlib._bootstrap>", line 488, in _call_with_frames_removed
  File "/opt/airflow/dags/verdemar_etl.py", line 4, in <module>
    from astro import sql as aql
ModuleNotFoundError: No module named 'astro'
[2024-04-13T05:49:39.513+0000] {processor.py:842} WARNING - No viable dags retrieved from /opt/airflow/dags/verdemar_etl.py
[2024-04-13T05:49:39.538+0000] {processor.py:183} INFO - Processing /opt/airflow/dags/verdemar_etl.py took 0.300 seconds
[2024-04-13T05:50:10.078+0000] {processor.py:161} INFO - Started process (PID=2248) to work on /opt/airflow/dags/verdemar_etl.py
[2024-04-13T05:50:10.080+0000] {processor.py:830} INFO - Processing file /opt/airflow/dags/verdemar_etl.py for tasks to queue
[2024-04-13T05:50:10.084+0000] {logging_mixin.py:188} INFO - [2024-04-13T05:50:10.083+0000] {dagbag.py:540} INFO - Filling up the DagBag from /opt/airflow/dags/verdemar_etl.py
[2024-04-13T05:50:10.337+0000] {logging_mixin.py:188} INFO - [2024-04-13T05:50:10.335+0000] {dagbag.py:350} ERROR - Failed to import: /opt/airflow/dags/verdemar_etl.py
Traceback (most recent call last):
  File "/home/airflow/.local/lib/python3.12/site-packages/airflow/models/dagbag.py", line 346, in parse
    loader.exec_module(new_module)
  File "<frozen importlib._bootstrap_external>", line 995, in exec_module
  File "<frozen importlib._bootstrap>", line 488, in _call_with_frames_removed
  File "/opt/airflow/dags/verdemar_etl.py", line 4, in <module>
    from astro import sql as aql
ModuleNotFoundError: No module named 'astro'
[2024-04-13T05:50:10.338+0000] {processor.py:842} WARNING - No viable dags retrieved from /opt/airflow/dags/verdemar_etl.py
[2024-04-13T05:50:10.359+0000] {processor.py:183} INFO - Processing /opt/airflow/dags/verdemar_etl.py took 0.295 seconds
[2024-04-13T05:50:28.961+0000] {processor.py:161} INFO - Started process (PID=2283) to work on /opt/airflow/dags/verdemar_etl.py
[2024-04-13T05:50:28.964+0000] {processor.py:830} INFO - Processing file /opt/airflow/dags/verdemar_etl.py for tasks to queue
[2024-04-13T05:50:28.967+0000] {logging_mixin.py:188} INFO - [2024-04-13T05:50:28.966+0000] {dagbag.py:540} INFO - Filling up the DagBag from /opt/airflow/dags/verdemar_etl.py
[2024-04-13T05:50:29.369+0000] {logging_mixin.py:188} INFO - [2024-04-13T05:50:29.367+0000] {dagbag.py:350} ERROR - Failed to import: /opt/airflow/dags/verdemar_etl.py
Traceback (most recent call last):
  File "/home/airflow/.local/lib/python3.12/site-packages/airflow/models/dagbag.py", line 346, in parse
    loader.exec_module(new_module)
  File "<frozen importlib._bootstrap_external>", line 995, in exec_module
  File "<frozen importlib._bootstrap>", line 488, in _call_with_frames_removed
  File "/opt/airflow/dags/verdemar_etl.py", line 4, in <module>
    from astro import sql as aql
ModuleNotFoundError: No module named 'astro'
[2024-04-13T05:50:29.369+0000] {processor.py:842} WARNING - No viable dags retrieved from /opt/airflow/dags/verdemar_etl.py
[2024-04-13T05:50:29.392+0000] {processor.py:183} INFO - Processing /opt/airflow/dags/verdemar_etl.py took 0.442 seconds
[2024-04-13T05:50:47.207+0000] {processor.py:161} INFO - Started process (PID=2312) to work on /opt/airflow/dags/verdemar_etl.py
[2024-04-13T05:50:47.209+0000] {processor.py:830} INFO - Processing file /opt/airflow/dags/verdemar_etl.py for tasks to queue
[2024-04-13T05:50:47.213+0000] {logging_mixin.py:188} INFO - [2024-04-13T05:50:47.212+0000] {dagbag.py:540} INFO - Filling up the DagBag from /opt/airflow/dags/verdemar_etl.py
[2024-04-13T05:50:47.220+0000] {logging_mixin.py:188} INFO - [2024-04-13T05:50:47.218+0000] {dagbag.py:350} ERROR - Failed to import: /opt/airflow/dags/verdemar_etl.py
Traceback (most recent call last):
  File "/home/airflow/.local/lib/python3.12/site-packages/airflow/models/dagbag.py", line 346, in parse
    loader.exec_module(new_module)
  File "<frozen importlib._bootstrap_external>", line 991, in exec_module
  File "<frozen importlib._bootstrap_external>", line 1129, in get_code
  File "<frozen importlib._bootstrap_external>", line 1059, in source_to_code
  File "<frozen importlib._bootstrap>", line 488, in _call_with_frames_removed
  File "/opt/airflow/dags/verdemar_etl.py", line 9
    S3_CONN_ID = 
                 ^
SyntaxError: invalid syntax
[2024-04-13T05:50:47.220+0000] {processor.py:842} WARNING - No viable dags retrieved from /opt/airflow/dags/verdemar_etl.py
[2024-04-13T05:50:47.252+0000] {processor.py:183} INFO - Processing /opt/airflow/dags/verdemar_etl.py took 0.065 seconds
[2024-04-13T05:51:08.285+0000] {processor.py:161} INFO - Started process (PID=2370) to work on /opt/airflow/dags/verdemar_etl.py
[2024-04-13T05:51:08.286+0000] {processor.py:830} INFO - Processing file /opt/airflow/dags/verdemar_etl.py for tasks to queue
[2024-04-13T05:51:08.289+0000] {logging_mixin.py:188} INFO - [2024-04-13T05:51:08.288+0000] {dagbag.py:540} INFO - Filling up the DagBag from /opt/airflow/dags/verdemar_etl.py
[2024-04-13T05:51:08.580+0000] {logging_mixin.py:188} INFO - [2024-04-13T05:51:08.578+0000] {dagbag.py:350} ERROR - Failed to import: /opt/airflow/dags/verdemar_etl.py
Traceback (most recent call last):
  File "/home/airflow/.local/lib/python3.12/site-packages/airflow/models/dagbag.py", line 346, in parse
    loader.exec_module(new_module)
  File "<frozen importlib._bootstrap_external>", line 995, in exec_module
  File "<frozen importlib._bootstrap>", line 488, in _call_with_frames_removed
  File "/opt/airflow/dags/verdemar_etl.py", line 4, in <module>
    from astro import sql as aql
ModuleNotFoundError: No module named 'astro'
[2024-04-13T05:51:08.580+0000] {processor.py:842} WARNING - No viable dags retrieved from /opt/airflow/dags/verdemar_etl.py
[2024-04-13T05:51:08.609+0000] {processor.py:183} INFO - Processing /opt/airflow/dags/verdemar_etl.py took 0.332 seconds
[2024-04-13T05:51:36.778+0000] {processor.py:161} INFO - Started process (PID=2431) to work on /opt/airflow/dags/verdemar_etl.py
[2024-04-13T05:51:36.780+0000] {processor.py:830} INFO - Processing file /opt/airflow/dags/verdemar_etl.py for tasks to queue
[2024-04-13T05:51:36.786+0000] {logging_mixin.py:188} INFO - [2024-04-13T05:51:36.785+0000] {dagbag.py:540} INFO - Filling up the DagBag from /opt/airflow/dags/verdemar_etl.py
[2024-04-13T05:51:36.799+0000] {logging_mixin.py:188} INFO - [2024-04-13T05:51:36.797+0000] {dagbag.py:350} ERROR - Failed to import: /opt/airflow/dags/verdemar_etl.py
Traceback (most recent call last):
  File "/home/airflow/.local/lib/python3.12/site-packages/airflow/models/dagbag.py", line 346, in parse
    loader.exec_module(new_module)
  File "<frozen importlib._bootstrap_external>", line 991, in exec_module
  File "<frozen importlib._bootstrap_external>", line 1129, in get_code
  File "<frozen importlib._bootstrap_external>", line 1059, in source_to_code
  File "<frozen importlib._bootstrap>", line 488, in _call_with_frames_removed
  File "/opt/airflow/dags/verdemar_etl.py", line 12
    with DAG(dag_id=)
             ^^^^^^^
SyntaxError: expected argument value expression
[2024-04-13T05:51:36.799+0000] {processor.py:842} WARNING - No viable dags retrieved from /opt/airflow/dags/verdemar_etl.py
[2024-04-13T05:51:36.818+0000] {processor.py:183} INFO - Processing /opt/airflow/dags/verdemar_etl.py took 0.048 seconds
[2024-04-13T05:52:07.030+0000] {processor.py:161} INFO - Started process (PID=2491) to work on /opt/airflow/dags/verdemar_etl.py
[2024-04-13T05:52:07.032+0000] {processor.py:830} INFO - Processing file /opt/airflow/dags/verdemar_etl.py for tasks to queue
[2024-04-13T05:52:07.034+0000] {logging_mixin.py:188} INFO - [2024-04-13T05:52:07.034+0000] {dagbag.py:540} INFO - Filling up the DagBag from /opt/airflow/dags/verdemar_etl.py
[2024-04-13T05:52:07.039+0000] {logging_mixin.py:188} INFO - [2024-04-13T05:52:07.038+0000] {dagbag.py:350} ERROR - Failed to import: /opt/airflow/dags/verdemar_etl.py
Traceback (most recent call last):
  File "/home/airflow/.local/lib/python3.12/site-packages/airflow/models/dagbag.py", line 346, in parse
    loader.exec_module(new_module)
  File "<frozen importlib._bootstrap_external>", line 991, in exec_module
  File "<frozen importlib._bootstrap_external>", line 1129, in get_code
  File "<frozen importlib._bootstrap_external>", line 1059, in source_to_code
  File "<frozen importlib._bootstrap>", line 488, in _call_with_frames_removed
  File "/opt/airflow/dags/verdemar_etl.py", line 12
    with DAG(dag_id=)
             ^^^^^^^
SyntaxError: expected argument value expression
[2024-04-13T05:52:07.039+0000] {processor.py:842} WARNING - No viable dags retrieved from /opt/airflow/dags/verdemar_etl.py
[2024-04-13T05:52:07.052+0000] {processor.py:183} INFO - Processing /opt/airflow/dags/verdemar_etl.py took 0.027 seconds
[2024-04-13T05:52:37.190+0000] {processor.py:161} INFO - Started process (PID=2551) to work on /opt/airflow/dags/verdemar_etl.py
[2024-04-13T05:52:37.191+0000] {processor.py:830} INFO - Processing file /opt/airflow/dags/verdemar_etl.py for tasks to queue
[2024-04-13T05:52:37.194+0000] {logging_mixin.py:188} INFO - [2024-04-13T05:52:37.194+0000] {dagbag.py:540} INFO - Filling up the DagBag from /opt/airflow/dags/verdemar_etl.py
[2024-04-13T05:52:37.200+0000] {logging_mixin.py:188} INFO - [2024-04-13T05:52:37.199+0000] {dagbag.py:350} ERROR - Failed to import: /opt/airflow/dags/verdemar_etl.py
Traceback (most recent call last):
  File "/home/airflow/.local/lib/python3.12/site-packages/airflow/models/dagbag.py", line 346, in parse
    loader.exec_module(new_module)
  File "<frozen importlib._bootstrap_external>", line 991, in exec_module
  File "<frozen importlib._bootstrap_external>", line 1129, in get_code
  File "<frozen importlib._bootstrap_external>", line 1059, in source_to_code
  File "<frozen importlib._bootstrap>", line 488, in _call_with_frames_removed
  File "/opt/airflow/dags/verdemar_etl.py", line 12
    with DAG(dag_id=)
             ^^^^^^^
SyntaxError: expected argument value expression
[2024-04-13T05:52:37.201+0000] {processor.py:842} WARNING - No viable dags retrieved from /opt/airflow/dags/verdemar_etl.py
[2024-04-13T05:52:37.219+0000] {processor.py:183} INFO - Processing /opt/airflow/dags/verdemar_etl.py took 0.038 seconds
[2024-04-13T05:53:07.687+0000] {processor.py:161} INFO - Started process (PID=2611) to work on /opt/airflow/dags/verdemar_etl.py
[2024-04-13T05:53:07.688+0000] {processor.py:830} INFO - Processing file /opt/airflow/dags/verdemar_etl.py for tasks to queue
[2024-04-13T05:53:07.692+0000] {logging_mixin.py:188} INFO - [2024-04-13T05:53:07.691+0000] {dagbag.py:540} INFO - Filling up the DagBag from /opt/airflow/dags/verdemar_etl.py
[2024-04-13T05:53:07.697+0000] {logging_mixin.py:188} INFO - [2024-04-13T05:53:07.696+0000] {dagbag.py:350} ERROR - Failed to import: /opt/airflow/dags/verdemar_etl.py
Traceback (most recent call last):
  File "/home/airflow/.local/lib/python3.12/site-packages/airflow/models/dagbag.py", line 346, in parse
    loader.exec_module(new_module)
  File "<frozen importlib._bootstrap_external>", line 991, in exec_module
  File "<frozen importlib._bootstrap_external>", line 1129, in get_code
  File "<frozen importlib._bootstrap_external>", line 1059, in source_to_code
  File "<frozen importlib._bootstrap>", line 488, in _call_with_frames_removed
  File "/opt/airflow/dags/verdemar_etl.py", line 12
    with DAG(dag_id=)
             ^^^^^^^
SyntaxError: expected argument value expression
[2024-04-13T05:53:07.698+0000] {processor.py:842} WARNING - No viable dags retrieved from /opt/airflow/dags/verdemar_etl.py
[2024-04-13T05:53:07.717+0000] {processor.py:183} INFO - Processing /opt/airflow/dags/verdemar_etl.py took 0.046 seconds
[2024-04-13T05:53:37.855+0000] {processor.py:161} INFO - Started process (PID=2671) to work on /opt/airflow/dags/verdemar_etl.py
[2024-04-13T05:53:37.856+0000] {processor.py:830} INFO - Processing file /opt/airflow/dags/verdemar_etl.py for tasks to queue
[2024-04-13T05:53:37.858+0000] {logging_mixin.py:188} INFO - [2024-04-13T05:53:37.857+0000] {dagbag.py:540} INFO - Filling up the DagBag from /opt/airflow/dags/verdemar_etl.py
[2024-04-13T05:53:37.862+0000] {logging_mixin.py:188} INFO - [2024-04-13T05:53:37.861+0000] {dagbag.py:350} ERROR - Failed to import: /opt/airflow/dags/verdemar_etl.py
Traceback (most recent call last):
  File "/home/airflow/.local/lib/python3.12/site-packages/airflow/models/dagbag.py", line 346, in parse
    loader.exec_module(new_module)
  File "<frozen importlib._bootstrap_external>", line 991, in exec_module
  File "<frozen importlib._bootstrap_external>", line 1129, in get_code
  File "<frozen importlib._bootstrap_external>", line 1059, in source_to_code
  File "<frozen importlib._bootstrap>", line 488, in _call_with_frames_removed
  File "/opt/airflow/dags/verdemar_etl.py", line 12
    with DAG(dag_id=)
             ^^^^^^^
SyntaxError: expected argument value expression
[2024-04-13T05:53:37.862+0000] {processor.py:842} WARNING - No viable dags retrieved from /opt/airflow/dags/verdemar_etl.py
[2024-04-13T05:53:37.876+0000] {processor.py:183} INFO - Processing /opt/airflow/dags/verdemar_etl.py took 0.026 seconds
[2024-04-13T05:54:08.661+0000] {processor.py:161} INFO - Started process (PID=2731) to work on /opt/airflow/dags/verdemar_etl.py
[2024-04-13T05:54:08.662+0000] {processor.py:830} INFO - Processing file /opt/airflow/dags/verdemar_etl.py for tasks to queue
[2024-04-13T05:54:08.666+0000] {logging_mixin.py:188} INFO - [2024-04-13T05:54:08.665+0000] {dagbag.py:540} INFO - Filling up the DagBag from /opt/airflow/dags/verdemar_etl.py
[2024-04-13T05:54:08.673+0000] {logging_mixin.py:188} INFO - [2024-04-13T05:54:08.671+0000] {dagbag.py:350} ERROR - Failed to import: /opt/airflow/dags/verdemar_etl.py
Traceback (most recent call last):
  File "/home/airflow/.local/lib/python3.12/site-packages/airflow/models/dagbag.py", line 346, in parse
    loader.exec_module(new_module)
  File "<frozen importlib._bootstrap_external>", line 991, in exec_module
  File "<frozen importlib._bootstrap_external>", line 1129, in get_code
  File "<frozen importlib._bootstrap_external>", line 1059, in source_to_code
  File "<frozen importlib._bootstrap>", line 488, in _call_with_frames_removed
  File "/opt/airflow/dags/verdemar_etl.py", line 12
    with DAG(dag_id=)
             ^^^^^^^
SyntaxError: expected argument value expression
[2024-04-13T05:54:08.673+0000] {processor.py:842} WARNING - No viable dags retrieved from /opt/airflow/dags/verdemar_etl.py
[2024-04-13T05:54:08.692+0000] {processor.py:183} INFO - Processing /opt/airflow/dags/verdemar_etl.py took 0.045 seconds
[2024-04-13T05:54:16.979+0000] {processor.py:161} INFO - Started process (PID=2732) to work on /opt/airflow/dags/verdemar_etl.py
[2024-04-13T05:54:16.980+0000] {processor.py:830} INFO - Processing file /opt/airflow/dags/verdemar_etl.py for tasks to queue
[2024-04-13T05:54:16.984+0000] {logging_mixin.py:188} INFO - [2024-04-13T05:54:16.983+0000] {dagbag.py:540} INFO - Filling up the DagBag from /opt/airflow/dags/verdemar_etl.py
[2024-04-13T05:54:16.989+0000] {logging_mixin.py:188} INFO - [2024-04-13T05:54:16.988+0000] {dagbag.py:350} ERROR - Failed to import: /opt/airflow/dags/verdemar_etl.py
Traceback (most recent call last):
  File "/home/airflow/.local/lib/python3.12/site-packages/airflow/models/dagbag.py", line 346, in parse
    loader.exec_module(new_module)
  File "<frozen importlib._bootstrap_external>", line 991, in exec_module
  File "<frozen importlib._bootstrap_external>", line 1129, in get_code
  File "<frozen importlib._bootstrap_external>", line 1059, in source_to_code
  File "<frozen importlib._bootstrap>", line 488, in _call_with_frames_removed
  File "/opt/airflow/dags/verdemar_etl.py", line 22
    aql.write(df, table
             ^
SyntaxError: '(' was never closed
[2024-04-13T05:54:16.989+0000] {processor.py:842} WARNING - No viable dags retrieved from /opt/airflow/dags/verdemar_etl.py
[2024-04-13T05:54:17.034+0000] {processor.py:183} INFO - Processing /opt/airflow/dags/verdemar_etl.py took 0.070 seconds
[2024-04-13T05:54:47.527+0000] {processor.py:161} INFO - Started process (PID=2792) to work on /opt/airflow/dags/verdemar_etl.py
[2024-04-13T05:54:47.529+0000] {processor.py:830} INFO - Processing file /opt/airflow/dags/verdemar_etl.py for tasks to queue
[2024-04-13T05:54:47.532+0000] {logging_mixin.py:188} INFO - [2024-04-13T05:54:47.532+0000] {dagbag.py:540} INFO - Filling up the DagBag from /opt/airflow/dags/verdemar_etl.py
[2024-04-13T05:54:47.539+0000] {logging_mixin.py:188} INFO - [2024-04-13T05:54:47.538+0000] {dagbag.py:350} ERROR - Failed to import: /opt/airflow/dags/verdemar_etl.py
Traceback (most recent call last):
  File "/home/airflow/.local/lib/python3.12/site-packages/airflow/models/dagbag.py", line 346, in parse
    loader.exec_module(new_module)
  File "<frozen importlib._bootstrap_external>", line 991, in exec_module
  File "<frozen importlib._bootstrap_external>", line 1129, in get_code
  File "<frozen importlib._bootstrap_external>", line 1059, in source_to_code
  File "<frozen importlib._bootstrap>", line 488, in _call_with_frames_removed
  File "/opt/airflow/dags/verdemar_etl.py", line 22
    aql.write(df, table
             ^
SyntaxError: '(' was never closed
[2024-04-13T05:54:47.539+0000] {processor.py:842} WARNING - No viable dags retrieved from /opt/airflow/dags/verdemar_etl.py
[2024-04-13T05:54:47.581+0000] {processor.py:183} INFO - Processing /opt/airflow/dags/verdemar_etl.py took 0.069 seconds
[2024-04-13T05:55:18.009+0000] {processor.py:161} INFO - Started process (PID=2852) to work on /opt/airflow/dags/verdemar_etl.py
[2024-04-13T05:55:18.012+0000] {processor.py:830} INFO - Processing file /opt/airflow/dags/verdemar_etl.py for tasks to queue
[2024-04-13T05:55:18.015+0000] {logging_mixin.py:188} INFO - [2024-04-13T05:55:18.015+0000] {dagbag.py:540} INFO - Filling up the DagBag from /opt/airflow/dags/verdemar_etl.py
[2024-04-13T05:55:18.021+0000] {logging_mixin.py:188} INFO - [2024-04-13T05:55:18.020+0000] {dagbag.py:350} ERROR - Failed to import: /opt/airflow/dags/verdemar_etl.py
Traceback (most recent call last):
  File "/home/airflow/.local/lib/python3.12/site-packages/airflow/models/dagbag.py", line 346, in parse
    loader.exec_module(new_module)
  File "<frozen importlib._bootstrap_external>", line 991, in exec_module
  File "<frozen importlib._bootstrap_external>", line 1129, in get_code
  File "<frozen importlib._bootstrap_external>", line 1059, in source_to_code
  File "<frozen importlib._bootstrap>", line 488, in _call_with_frames_removed
  File "/opt/airflow/dags/verdemar_etl.py", line 22
    aql.write(df, table
             ^
SyntaxError: '(' was never closed
[2024-04-13T05:55:18.022+0000] {processor.py:842} WARNING - No viable dags retrieved from /opt/airflow/dags/verdemar_etl.py
[2024-04-13T05:55:18.044+0000] {processor.py:183} INFO - Processing /opt/airflow/dags/verdemar_etl.py took 0.046 seconds
[2024-04-13T05:55:48.263+0000] {processor.py:161} INFO - Started process (PID=2912) to work on /opt/airflow/dags/verdemar_etl.py
[2024-04-13T05:55:48.265+0000] {processor.py:830} INFO - Processing file /opt/airflow/dags/verdemar_etl.py for tasks to queue
[2024-04-13T05:55:48.269+0000] {logging_mixin.py:188} INFO - [2024-04-13T05:55:48.268+0000] {dagbag.py:540} INFO - Filling up the DagBag from /opt/airflow/dags/verdemar_etl.py
[2024-04-13T05:55:48.275+0000] {logging_mixin.py:188} INFO - [2024-04-13T05:55:48.274+0000] {dagbag.py:350} ERROR - Failed to import: /opt/airflow/dags/verdemar_etl.py
Traceback (most recent call last):
  File "/home/airflow/.local/lib/python3.12/site-packages/airflow/models/dagbag.py", line 346, in parse
    loader.exec_module(new_module)
  File "<frozen importlib._bootstrap_external>", line 991, in exec_module
  File "<frozen importlib._bootstrap_external>", line 1129, in get_code
  File "<frozen importlib._bootstrap_external>", line 1059, in source_to_code
  File "<frozen importlib._bootstrap>", line 488, in _call_with_frames_removed
  File "/opt/airflow/dags/verdemar_etl.py", line 22
    aql.write(df, table
             ^
SyntaxError: '(' was never closed
[2024-04-13T05:55:48.276+0000] {processor.py:842} WARNING - No viable dags retrieved from /opt/airflow/dags/verdemar_etl.py
[2024-04-13T05:55:48.295+0000] {processor.py:183} INFO - Processing /opt/airflow/dags/verdemar_etl.py took 0.047 seconds
[2024-04-13T05:56:18.553+0000] {processor.py:161} INFO - Started process (PID=2971) to work on /opt/airflow/dags/verdemar_etl.py
[2024-04-13T05:56:18.575+0000] {processor.py:830} INFO - Processing file /opt/airflow/dags/verdemar_etl.py for tasks to queue
[2024-04-13T05:56:18.586+0000] {logging_mixin.py:188} INFO - [2024-04-13T05:56:18.585+0000] {dagbag.py:540} INFO - Filling up the DagBag from /opt/airflow/dags/verdemar_etl.py
[2024-04-13T05:56:18.593+0000] {logging_mixin.py:188} INFO - [2024-04-13T05:56:18.591+0000] {dagbag.py:350} ERROR - Failed to import: /opt/airflow/dags/verdemar_etl.py
Traceback (most recent call last):
  File "/home/airflow/.local/lib/python3.12/site-packages/airflow/models/dagbag.py", line 346, in parse
    loader.exec_module(new_module)
  File "<frozen importlib._bootstrap_external>", line 991, in exec_module
  File "<frozen importlib._bootstrap_external>", line 1129, in get_code
  File "<frozen importlib._bootstrap_external>", line 1059, in source_to_code
  File "<frozen importlib._bootstrap>", line 488, in _call_with_frames_removed
  File "/opt/airflow/dags/verdemar_etl.py", line 22
    aql.write(df, table
             ^
SyntaxError: '(' was never closed
[2024-04-13T05:56:18.593+0000] {processor.py:842} WARNING - No viable dags retrieved from /opt/airflow/dags/verdemar_etl.py
[2024-04-13T05:56:18.616+0000] {processor.py:183} INFO - Processing /opt/airflow/dags/verdemar_etl.py took 0.073 seconds
[2024-04-13T05:56:49.105+0000] {processor.py:161} INFO - Started process (PID=3031) to work on /opt/airflow/dags/verdemar_etl.py
[2024-04-13T05:56:49.108+0000] {processor.py:830} INFO - Processing file /opt/airflow/dags/verdemar_etl.py for tasks to queue
[2024-04-13T05:56:49.111+0000] {logging_mixin.py:188} INFO - [2024-04-13T05:56:49.111+0000] {dagbag.py:540} INFO - Filling up the DagBag from /opt/airflow/dags/verdemar_etl.py
[2024-04-13T05:56:49.118+0000] {logging_mixin.py:188} INFO - [2024-04-13T05:56:49.117+0000] {dagbag.py:350} ERROR - Failed to import: /opt/airflow/dags/verdemar_etl.py
Traceback (most recent call last):
  File "/home/airflow/.local/lib/python3.12/site-packages/airflow/models/dagbag.py", line 346, in parse
    loader.exec_module(new_module)
  File "<frozen importlib._bootstrap_external>", line 991, in exec_module
  File "<frozen importlib._bootstrap_external>", line 1129, in get_code
  File "<frozen importlib._bootstrap_external>", line 1059, in source_to_code
  File "<frozen importlib._bootstrap>", line 488, in _call_with_frames_removed
  File "/opt/airflow/dags/verdemar_etl.py", line 22
    aql.write(df, table
             ^
SyntaxError: '(' was never closed
[2024-04-13T05:56:49.119+0000] {processor.py:842} WARNING - No viable dags retrieved from /opt/airflow/dags/verdemar_etl.py
[2024-04-13T05:56:49.153+0000] {processor.py:183} INFO - Processing /opt/airflow/dags/verdemar_etl.py took 0.057 seconds
[2024-04-13T05:57:19.386+0000] {processor.py:161} INFO - Started process (PID=3091) to work on /opt/airflow/dags/verdemar_etl.py
[2024-04-13T05:57:19.387+0000] {processor.py:830} INFO - Processing file /opt/airflow/dags/verdemar_etl.py for tasks to queue
[2024-04-13T05:57:19.391+0000] {logging_mixin.py:188} INFO - [2024-04-13T05:57:19.390+0000] {dagbag.py:540} INFO - Filling up the DagBag from /opt/airflow/dags/verdemar_etl.py
[2024-04-13T05:57:19.405+0000] {logging_mixin.py:188} INFO - [2024-04-13T05:57:19.399+0000] {dagbag.py:350} ERROR - Failed to import: /opt/airflow/dags/verdemar_etl.py
Traceback (most recent call last):
  File "/home/airflow/.local/lib/python3.12/site-packages/airflow/models/dagbag.py", line 346, in parse
    loader.exec_module(new_module)
  File "<frozen importlib._bootstrap_external>", line 991, in exec_module
  File "<frozen importlib._bootstrap_external>", line 1129, in get_code
  File "<frozen importlib._bootstrap_external>", line 1059, in source_to_code
  File "<frozen importlib._bootstrap>", line 488, in _call_with_frames_removed
  File "/opt/airflow/dags/verdemar_etl.py", line 22
    aql.write(df, table
             ^
SyntaxError: '(' was never closed
[2024-04-13T05:57:19.406+0000] {processor.py:842} WARNING - No viable dags retrieved from /opt/airflow/dags/verdemar_etl.py
[2024-04-13T05:57:19.446+0000] {processor.py:183} INFO - Processing /opt/airflow/dags/verdemar_etl.py took 0.070 seconds
[2024-04-13T05:57:45.469+0000] {processor.py:161} INFO - Started process (PID=3151) to work on /opt/airflow/dags/verdemar_etl.py
[2024-04-13T05:57:45.471+0000] {processor.py:830} INFO - Processing file /opt/airflow/dags/verdemar_etl.py for tasks to queue
[2024-04-13T05:57:45.475+0000] {logging_mixin.py:188} INFO - [2024-04-13T05:57:45.475+0000] {dagbag.py:540} INFO - Filling up the DagBag from /opt/airflow/dags/verdemar_etl.py
[2024-04-13T05:57:45.482+0000] {logging_mixin.py:188} INFO - [2024-04-13T05:57:45.481+0000] {dagbag.py:350} ERROR - Failed to import: /opt/airflow/dags/verdemar_etl.py
Traceback (most recent call last):
  File "/home/airflow/.local/lib/python3.12/site-packages/airflow/models/dagbag.py", line 346, in parse
    loader.exec_module(new_module)
  File "<frozen importlib._bootstrap_external>", line 991, in exec_module
  File "<frozen importlib._bootstrap_external>", line 1129, in get_code
  File "<frozen importlib._bootstrap_external>", line 1059, in source_to_code
  File "<frozen importlib._bootstrap>", line 488, in _call_with_frames_removed
  File "/opt/airflow/dags/verdemar_etl.py", line 14
    input_file = File(
IndentationError: unexpected indent
[2024-04-13T05:57:45.482+0000] {processor.py:842} WARNING - No viable dags retrieved from /opt/airflow/dags/verdemar_etl.py
[2024-04-13T05:57:45.503+0000] {processor.py:183} INFO - Processing /opt/airflow/dags/verdemar_etl.py took 0.056 seconds
[2024-04-13T05:58:16.280+0000] {processor.py:161} INFO - Started process (PID=3211) to work on /opt/airflow/dags/verdemar_etl.py
[2024-04-13T05:58:16.282+0000] {processor.py:830} INFO - Processing file /opt/airflow/dags/verdemar_etl.py for tasks to queue
[2024-04-13T05:58:16.286+0000] {logging_mixin.py:188} INFO - [2024-04-13T05:58:16.285+0000] {dagbag.py:540} INFO - Filling up the DagBag from /opt/airflow/dags/verdemar_etl.py
[2024-04-13T05:58:16.300+0000] {logging_mixin.py:188} INFO - [2024-04-13T05:58:16.293+0000] {dagbag.py:350} ERROR - Failed to import: /opt/airflow/dags/verdemar_etl.py
Traceback (most recent call last):
  File "/home/airflow/.local/lib/python3.12/site-packages/airflow/models/dagbag.py", line 346, in parse
    loader.exec_module(new_module)
  File "<frozen importlib._bootstrap_external>", line 991, in exec_module
  File "<frozen importlib._bootstrap_external>", line 1129, in get_code
  File "<frozen importlib._bootstrap_external>", line 1059, in source_to_code
  File "<frozen importlib._bootstrap>", line 488, in _call_with_frames_removed
  File "/opt/airflow/dags/verdemar_etl.py", line 14
    input_file = File(
IndentationError: unexpected indent
[2024-04-13T05:58:16.302+0000] {processor.py:842} WARNING - No viable dags retrieved from /opt/airflow/dags/verdemar_etl.py
[2024-04-13T05:58:16.349+0000] {processor.py:183} INFO - Processing /opt/airflow/dags/verdemar_etl.py took 0.077 seconds
[2024-04-13T05:58:46.810+0000] {processor.py:161} INFO - Started process (PID=3271) to work on /opt/airflow/dags/verdemar_etl.py
[2024-04-13T05:58:46.812+0000] {processor.py:830} INFO - Processing file /opt/airflow/dags/verdemar_etl.py for tasks to queue
[2024-04-13T05:58:46.815+0000] {logging_mixin.py:188} INFO - [2024-04-13T05:58:46.814+0000] {dagbag.py:540} INFO - Filling up the DagBag from /opt/airflow/dags/verdemar_etl.py
[2024-04-13T05:58:46.822+0000] {logging_mixin.py:188} INFO - [2024-04-13T05:58:46.820+0000] {dagbag.py:350} ERROR - Failed to import: /opt/airflow/dags/verdemar_etl.py
Traceback (most recent call last):
  File "/home/airflow/.local/lib/python3.12/site-packages/airflow/models/dagbag.py", line 346, in parse
    loader.exec_module(new_module)
  File "<frozen importlib._bootstrap_external>", line 991, in exec_module
  File "<frozen importlib._bootstrap_external>", line 1129, in get_code
  File "<frozen importlib._bootstrap_external>", line 1059, in source_to_code
  File "<frozen importlib._bootstrap>", line 488, in _call_with_frames_removed
  File "/opt/airflow/dags/verdemar_etl.py", line 14
    input_file = File(
IndentationError: unexpected indent
[2024-04-13T05:58:46.822+0000] {processor.py:842} WARNING - No viable dags retrieved from /opt/airflow/dags/verdemar_etl.py
[2024-04-13T05:58:46.840+0000] {processor.py:183} INFO - Processing /opt/airflow/dags/verdemar_etl.py took 0.038 seconds
[2024-04-13T05:59:16.880+0000] {processor.py:161} INFO - Started process (PID=3331) to work on /opt/airflow/dags/verdemar_etl.py
[2024-04-13T05:59:16.881+0000] {processor.py:830} INFO - Processing file /opt/airflow/dags/verdemar_etl.py for tasks to queue
[2024-04-13T05:59:16.884+0000] {logging_mixin.py:188} INFO - [2024-04-13T05:59:16.884+0000] {dagbag.py:540} INFO - Filling up the DagBag from /opt/airflow/dags/verdemar_etl.py
[2024-04-13T05:59:16.889+0000] {logging_mixin.py:188} INFO - [2024-04-13T05:59:16.888+0000] {dagbag.py:350} ERROR - Failed to import: /opt/airflow/dags/verdemar_etl.py
Traceback (most recent call last):
  File "/home/airflow/.local/lib/python3.12/site-packages/airflow/models/dagbag.py", line 346, in parse
    loader.exec_module(new_module)
  File "<frozen importlib._bootstrap_external>", line 991, in exec_module
  File "<frozen importlib._bootstrap_external>", line 1129, in get_code
  File "<frozen importlib._bootstrap_external>", line 1059, in source_to_code
  File "<frozen importlib._bootstrap>", line 488, in _call_with_frames_removed
  File "/opt/airflow/dags/verdemar_etl.py", line 14
    input_file = File(
IndentationError: unexpected indent
[2024-04-13T05:59:16.890+0000] {processor.py:842} WARNING - No viable dags retrieved from /opt/airflow/dags/verdemar_etl.py
[2024-04-13T05:59:16.909+0000] {processor.py:183} INFO - Processing /opt/airflow/dags/verdemar_etl.py took 0.036 seconds
[2024-04-13T05:59:47.696+0000] {processor.py:161} INFO - Started process (PID=3391) to work on /opt/airflow/dags/verdemar_etl.py
[2024-04-13T05:59:47.698+0000] {processor.py:830} INFO - Processing file /opt/airflow/dags/verdemar_etl.py for tasks to queue
[2024-04-13T05:59:47.701+0000] {logging_mixin.py:188} INFO - [2024-04-13T05:59:47.700+0000] {dagbag.py:540} INFO - Filling up the DagBag from /opt/airflow/dags/verdemar_etl.py
[2024-04-13T05:59:47.706+0000] {logging_mixin.py:188} INFO - [2024-04-13T05:59:47.705+0000] {dagbag.py:350} ERROR - Failed to import: /opt/airflow/dags/verdemar_etl.py
Traceback (most recent call last):
  File "/home/airflow/.local/lib/python3.12/site-packages/airflow/models/dagbag.py", line 346, in parse
    loader.exec_module(new_module)
  File "<frozen importlib._bootstrap_external>", line 991, in exec_module
  File "<frozen importlib._bootstrap_external>", line 1129, in get_code
  File "<frozen importlib._bootstrap_external>", line 1059, in source_to_code
  File "<frozen importlib._bootstrap>", line 488, in _call_with_frames_removed
  File "/opt/airflow/dags/verdemar_etl.py", line 14
    input_file = File(
IndentationError: unexpected indent
[2024-04-13T05:59:47.707+0000] {processor.py:842} WARNING - No viable dags retrieved from /opt/airflow/dags/verdemar_etl.py
[2024-04-13T05:59:47.722+0000] {processor.py:183} INFO - Processing /opt/airflow/dags/verdemar_etl.py took 0.033 seconds
[2024-04-13T06:00:17.823+0000] {processor.py:161} INFO - Started process (PID=3450) to work on /opt/airflow/dags/verdemar_etl.py
[2024-04-13T06:00:17.825+0000] {processor.py:830} INFO - Processing file /opt/airflow/dags/verdemar_etl.py for tasks to queue
[2024-04-13T06:00:17.827+0000] {logging_mixin.py:188} INFO - [2024-04-13T06:00:17.827+0000] {dagbag.py:540} INFO - Filling up the DagBag from /opt/airflow/dags/verdemar_etl.py
[2024-04-13T06:00:17.834+0000] {logging_mixin.py:188} INFO - [2024-04-13T06:00:17.833+0000] {dagbag.py:350} ERROR - Failed to import: /opt/airflow/dags/verdemar_etl.py
Traceback (most recent call last):
  File "/home/airflow/.local/lib/python3.12/site-packages/airflow/models/dagbag.py", line 346, in parse
    loader.exec_module(new_module)
  File "<frozen importlib._bootstrap_external>", line 991, in exec_module
  File "<frozen importlib._bootstrap_external>", line 1129, in get_code
  File "<frozen importlib._bootstrap_external>", line 1059, in source_to_code
  File "<frozen importlib._bootstrap>", line 488, in _call_with_frames_removed
  File "/opt/airflow/dags/verdemar_etl.py", line 14
    input_file = File(
IndentationError: unexpected indent
[2024-04-13T06:00:17.835+0000] {processor.py:842} WARNING - No viable dags retrieved from /opt/airflow/dags/verdemar_etl.py
[2024-04-13T06:00:17.850+0000] {processor.py:183} INFO - Processing /opt/airflow/dags/verdemar_etl.py took 0.037 seconds
[2024-04-13T06:00:42.379+0000] {processor.py:161} INFO - Started process (PID=3492) to work on /opt/airflow/dags/verdemar_etl.py
[2024-04-13T06:00:42.382+0000] {processor.py:830} INFO - Processing file /opt/airflow/dags/verdemar_etl.py for tasks to queue
[2024-04-13T06:00:42.390+0000] {logging_mixin.py:188} INFO - [2024-04-13T06:00:42.389+0000] {dagbag.py:540} INFO - Filling up the DagBag from /opt/airflow/dags/verdemar_etl.py
[2024-04-13T06:00:42.398+0000] {logging_mixin.py:188} INFO - [2024-04-13T06:00:42.397+0000] {dagbag.py:350} ERROR - Failed to import: /opt/airflow/dags/verdemar_etl.py
Traceback (most recent call last):
  File "/home/airflow/.local/lib/python3.12/site-packages/airflow/models/dagbag.py", line 346, in parse
    loader.exec_module(new_module)
  File "<frozen importlib._bootstrap_external>", line 991, in exec_module
  File "<frozen importlib._bootstrap_external>", line 1129, in get_code
  File "<frozen importlib._bootstrap_external>", line 1059, in source_to_code
  File "<frozen importlib._bootstrap>", line 488, in _call_with_frames_removed
  File "/opt/airflow/dags/verdemar_etl.py", line 14
    input_file = File(
IndentationError: unexpected indent
[2024-04-13T06:00:42.399+0000] {processor.py:842} WARNING - No viable dags retrieved from /opt/airflow/dags/verdemar_etl.py
[2024-04-13T06:00:42.416+0000] {processor.py:183} INFO - Processing /opt/airflow/dags/verdemar_etl.py took 0.052 seconds
[2024-04-13T06:01:12.635+0000] {processor.py:161} INFO - Started process (PID=3552) to work on /opt/airflow/dags/verdemar_etl.py
[2024-04-13T06:01:12.636+0000] {processor.py:830} INFO - Processing file /opt/airflow/dags/verdemar_etl.py for tasks to queue
[2024-04-13T06:01:12.638+0000] {logging_mixin.py:188} INFO - [2024-04-13T06:01:12.638+0000] {dagbag.py:540} INFO - Filling up the DagBag from /opt/airflow/dags/verdemar_etl.py
[2024-04-13T06:01:12.642+0000] {logging_mixin.py:188} INFO - [2024-04-13T06:01:12.641+0000] {dagbag.py:350} ERROR - Failed to import: /opt/airflow/dags/verdemar_etl.py
Traceback (most recent call last):
  File "/home/airflow/.local/lib/python3.12/site-packages/airflow/models/dagbag.py", line 346, in parse
    loader.exec_module(new_module)
  File "<frozen importlib._bootstrap_external>", line 991, in exec_module
  File "<frozen importlib._bootstrap_external>", line 1129, in get_code
  File "<frozen importlib._bootstrap_external>", line 1059, in source_to_code
  File "<frozen importlib._bootstrap>", line 488, in _call_with_frames_removed
  File "/opt/airflow/dags/verdemar_etl.py", line 14
    input_file = File(
IndentationError: unexpected indent
[2024-04-13T06:01:12.643+0000] {processor.py:842} WARNING - No viable dags retrieved from /opt/airflow/dags/verdemar_etl.py
[2024-04-13T06:01:12.654+0000] {processor.py:183} INFO - Processing /opt/airflow/dags/verdemar_etl.py took 0.026 seconds
[2024-04-13T06:01:42.701+0000] {processor.py:161} INFO - Started process (PID=3612) to work on /opt/airflow/dags/verdemar_etl.py
[2024-04-13T06:01:42.702+0000] {processor.py:830} INFO - Processing file /opt/airflow/dags/verdemar_etl.py for tasks to queue
[2024-04-13T06:01:42.703+0000] {logging_mixin.py:188} INFO - [2024-04-13T06:01:42.703+0000] {dagbag.py:540} INFO - Filling up the DagBag from /opt/airflow/dags/verdemar_etl.py
[2024-04-13T06:01:42.708+0000] {logging_mixin.py:188} INFO - [2024-04-13T06:01:42.707+0000] {dagbag.py:350} ERROR - Failed to import: /opt/airflow/dags/verdemar_etl.py
Traceback (most recent call last):
  File "/home/airflow/.local/lib/python3.12/site-packages/airflow/models/dagbag.py", line 346, in parse
    loader.exec_module(new_module)
  File "<frozen importlib._bootstrap_external>", line 991, in exec_module
  File "<frozen importlib._bootstrap_external>", line 1129, in get_code
  File "<frozen importlib._bootstrap_external>", line 1059, in source_to_code
  File "<frozen importlib._bootstrap>", line 488, in _call_with_frames_removed
  File "/opt/airflow/dags/verdemar_etl.py", line 14
    input_file = File(
IndentationError: unexpected indent
[2024-04-13T06:01:42.708+0000] {processor.py:842} WARNING - No viable dags retrieved from /opt/airflow/dags/verdemar_etl.py
[2024-04-13T06:01:42.725+0000] {processor.py:183} INFO - Processing /opt/airflow/dags/verdemar_etl.py took 0.030 seconds
[2024-04-13T06:02:12.949+0000] {processor.py:161} INFO - Started process (PID=3672) to work on /opt/airflow/dags/verdemar_etl.py
[2024-04-13T06:02:12.955+0000] {processor.py:830} INFO - Processing file /opt/airflow/dags/verdemar_etl.py for tasks to queue
[2024-04-13T06:02:12.965+0000] {logging_mixin.py:188} INFO - [2024-04-13T06:02:12.964+0000] {dagbag.py:540} INFO - Filling up the DagBag from /opt/airflow/dags/verdemar_etl.py
[2024-04-13T06:02:12.970+0000] {logging_mixin.py:188} INFO - [2024-04-13T06:02:12.969+0000] {dagbag.py:350} ERROR - Failed to import: /opt/airflow/dags/verdemar_etl.py
Traceback (most recent call last):
  File "/home/airflow/.local/lib/python3.12/site-packages/airflow/models/dagbag.py", line 346, in parse
    loader.exec_module(new_module)
  File "<frozen importlib._bootstrap_external>", line 991, in exec_module
  File "<frozen importlib._bootstrap_external>", line 1129, in get_code
  File "<frozen importlib._bootstrap_external>", line 1059, in source_to_code
  File "<frozen importlib._bootstrap>", line 488, in _call_with_frames_removed
  File "/opt/airflow/dags/verdemar_etl.py", line 14
    input_file = File(
IndentationError: unexpected indent
[2024-04-13T06:02:12.971+0000] {processor.py:842} WARNING - No viable dags retrieved from /opt/airflow/dags/verdemar_etl.py
[2024-04-13T06:02:12.992+0000] {processor.py:183} INFO - Processing /opt/airflow/dags/verdemar_etl.py took 0.056 seconds
[2024-04-13T06:02:43.207+0000] {processor.py:161} INFO - Started process (PID=3732) to work on /opt/airflow/dags/verdemar_etl.py
[2024-04-13T06:02:43.208+0000] {processor.py:830} INFO - Processing file /opt/airflow/dags/verdemar_etl.py for tasks to queue
[2024-04-13T06:02:43.211+0000] {logging_mixin.py:188} INFO - [2024-04-13T06:02:43.210+0000] {dagbag.py:540} INFO - Filling up the DagBag from /opt/airflow/dags/verdemar_etl.py
[2024-04-13T06:02:43.217+0000] {logging_mixin.py:188} INFO - [2024-04-13T06:02:43.216+0000] {dagbag.py:350} ERROR - Failed to import: /opt/airflow/dags/verdemar_etl.py
Traceback (most recent call last):
  File "/home/airflow/.local/lib/python3.12/site-packages/airflow/models/dagbag.py", line 346, in parse
    loader.exec_module(new_module)
  File "<frozen importlib._bootstrap_external>", line 991, in exec_module
  File "<frozen importlib._bootstrap_external>", line 1129, in get_code
  File "<frozen importlib._bootstrap_external>", line 1059, in source_to_code
  File "<frozen importlib._bootstrap>", line 488, in _call_with_frames_removed
  File "/opt/airflow/dags/verdemar_etl.py", line 14
    input_file = File(
IndentationError: unexpected indent
[2024-04-13T06:02:43.218+0000] {processor.py:842} WARNING - No viable dags retrieved from /opt/airflow/dags/verdemar_etl.py
[2024-04-13T06:02:43.234+0000] {processor.py:183} INFO - Processing /opt/airflow/dags/verdemar_etl.py took 0.036 seconds
[2024-04-13T06:03:13.396+0000] {processor.py:161} INFO - Started process (PID=3792) to work on /opt/airflow/dags/verdemar_etl.py
[2024-04-13T06:03:13.398+0000] {processor.py:830} INFO - Processing file /opt/airflow/dags/verdemar_etl.py for tasks to queue
[2024-04-13T06:03:13.400+0000] {logging_mixin.py:188} INFO - [2024-04-13T06:03:13.400+0000] {dagbag.py:540} INFO - Filling up the DagBag from /opt/airflow/dags/verdemar_etl.py
[2024-04-13T06:03:13.407+0000] {logging_mixin.py:188} INFO - [2024-04-13T06:03:13.405+0000] {dagbag.py:350} ERROR - Failed to import: /opt/airflow/dags/verdemar_etl.py
Traceback (most recent call last):
  File "/home/airflow/.local/lib/python3.12/site-packages/airflow/models/dagbag.py", line 346, in parse
    loader.exec_module(new_module)
  File "<frozen importlib._bootstrap_external>", line 991, in exec_module
  File "<frozen importlib._bootstrap_external>", line 1129, in get_code
  File "<frozen importlib._bootstrap_external>", line 1059, in source_to_code
  File "<frozen importlib._bootstrap>", line 488, in _call_with_frames_removed
  File "/opt/airflow/dags/verdemar_etl.py", line 14
    input_file = File(
IndentationError: unexpected indent
[2024-04-13T06:03:13.407+0000] {processor.py:842} WARNING - No viable dags retrieved from /opt/airflow/dags/verdemar_etl.py
[2024-04-13T06:03:13.424+0000] {processor.py:183} INFO - Processing /opt/airflow/dags/verdemar_etl.py took 0.040 seconds
[2024-04-13T06:03:43.735+0000] {processor.py:161} INFO - Started process (PID=3852) to work on /opt/airflow/dags/verdemar_etl.py
[2024-04-13T06:03:43.737+0000] {processor.py:830} INFO - Processing file /opt/airflow/dags/verdemar_etl.py for tasks to queue
[2024-04-13T06:03:43.741+0000] {logging_mixin.py:188} INFO - [2024-04-13T06:03:43.740+0000] {dagbag.py:540} INFO - Filling up the DagBag from /opt/airflow/dags/verdemar_etl.py
[2024-04-13T06:03:43.768+0000] {logging_mixin.py:188} INFO - [2024-04-13T06:03:43.766+0000] {dagbag.py:350} ERROR - Failed to import: /opt/airflow/dags/verdemar_etl.py
Traceback (most recent call last):
  File "/home/airflow/.local/lib/python3.12/site-packages/airflow/models/dagbag.py", line 346, in parse
    loader.exec_module(new_module)
  File "<frozen importlib._bootstrap_external>", line 991, in exec_module
  File "<frozen importlib._bootstrap_external>", line 1129, in get_code
  File "<frozen importlib._bootstrap_external>", line 1059, in source_to_code
  File "<frozen importlib._bootstrap>", line 488, in _call_with_frames_removed
  File "/opt/airflow/dags/verdemar_etl.py", line 14
    input_file = File(
IndentationError: unexpected indent
[2024-04-13T06:03:43.771+0000] {processor.py:842} WARNING - No viable dags retrieved from /opt/airflow/dags/verdemar_etl.py
[2024-04-13T06:03:43.797+0000] {processor.py:183} INFO - Processing /opt/airflow/dags/verdemar_etl.py took 0.073 seconds
[2024-04-13T06:04:13.962+0000] {processor.py:161} INFO - Started process (PID=3912) to work on /opt/airflow/dags/verdemar_etl.py
[2024-04-13T06:04:13.963+0000] {processor.py:830} INFO - Processing file /opt/airflow/dags/verdemar_etl.py for tasks to queue
[2024-04-13T06:04:13.965+0000] {logging_mixin.py:188} INFO - [2024-04-13T06:04:13.964+0000] {dagbag.py:540} INFO - Filling up the DagBag from /opt/airflow/dags/verdemar_etl.py
[2024-04-13T06:04:13.969+0000] {logging_mixin.py:188} INFO - [2024-04-13T06:04:13.968+0000] {dagbag.py:350} ERROR - Failed to import: /opt/airflow/dags/verdemar_etl.py
Traceback (most recent call last):
  File "/home/airflow/.local/lib/python3.12/site-packages/airflow/models/dagbag.py", line 346, in parse
    loader.exec_module(new_module)
  File "<frozen importlib._bootstrap_external>", line 991, in exec_module
  File "<frozen importlib._bootstrap_external>", line 1129, in get_code
  File "<frozen importlib._bootstrap_external>", line 1059, in source_to_code
  File "<frozen importlib._bootstrap>", line 488, in _call_with_frames_removed
  File "/opt/airflow/dags/verdemar_etl.py", line 14
    input_file = File(
IndentationError: unexpected indent
[2024-04-13T06:04:13.969+0000] {processor.py:842} WARNING - No viable dags retrieved from /opt/airflow/dags/verdemar_etl.py
[2024-04-13T06:04:13.995+0000] {processor.py:183} INFO - Processing /opt/airflow/dags/verdemar_etl.py took 0.038 seconds
[2024-04-13T06:04:44.537+0000] {processor.py:161} INFO - Started process (PID=3972) to work on /opt/airflow/dags/verdemar_etl.py
[2024-04-13T06:04:44.538+0000] {processor.py:830} INFO - Processing file /opt/airflow/dags/verdemar_etl.py for tasks to queue
[2024-04-13T06:04:44.540+0000] {logging_mixin.py:188} INFO - [2024-04-13T06:04:44.540+0000] {dagbag.py:540} INFO - Filling up the DagBag from /opt/airflow/dags/verdemar_etl.py
[2024-04-13T06:04:44.544+0000] {logging_mixin.py:188} INFO - [2024-04-13T06:04:44.543+0000] {dagbag.py:350} ERROR - Failed to import: /opt/airflow/dags/verdemar_etl.py
Traceback (most recent call last):
  File "/home/airflow/.local/lib/python3.12/site-packages/airflow/models/dagbag.py", line 346, in parse
    loader.exec_module(new_module)
  File "<frozen importlib._bootstrap_external>", line 991, in exec_module
  File "<frozen importlib._bootstrap_external>", line 1129, in get_code
  File "<frozen importlib._bootstrap_external>", line 1059, in source_to_code
  File "<frozen importlib._bootstrap>", line 488, in _call_with_frames_removed
  File "/opt/airflow/dags/verdemar_etl.py", line 14
    input_file = File(
IndentationError: unexpected indent
[2024-04-13T06:04:44.545+0000] {processor.py:842} WARNING - No viable dags retrieved from /opt/airflow/dags/verdemar_etl.py
[2024-04-13T06:04:44.556+0000] {processor.py:183} INFO - Processing /opt/airflow/dags/verdemar_etl.py took 0.024 seconds
[2024-04-13T06:05:14.994+0000] {processor.py:161} INFO - Started process (PID=4032) to work on /opt/airflow/dags/verdemar_etl.py
[2024-04-13T06:05:14.995+0000] {processor.py:830} INFO - Processing file /opt/airflow/dags/verdemar_etl.py for tasks to queue
[2024-04-13T06:05:14.997+0000] {logging_mixin.py:188} INFO - [2024-04-13T06:05:14.997+0000] {dagbag.py:540} INFO - Filling up the DagBag from /opt/airflow/dags/verdemar_etl.py
[2024-04-13T06:05:15.001+0000] {logging_mixin.py:188} INFO - [2024-04-13T06:05:15.001+0000] {dagbag.py:350} ERROR - Failed to import: /opt/airflow/dags/verdemar_etl.py
Traceback (most recent call last):
  File "/home/airflow/.local/lib/python3.12/site-packages/airflow/models/dagbag.py", line 346, in parse
    loader.exec_module(new_module)
  File "<frozen importlib._bootstrap_external>", line 991, in exec_module
  File "<frozen importlib._bootstrap_external>", line 1129, in get_code
  File "<frozen importlib._bootstrap_external>", line 1059, in source_to_code
  File "<frozen importlib._bootstrap>", line 488, in _call_with_frames_removed
  File "/opt/airflow/dags/verdemar_etl.py", line 14
    input_file = File(
IndentationError: unexpected indent
[2024-04-13T06:05:15.002+0000] {processor.py:842} WARNING - No viable dags retrieved from /opt/airflow/dags/verdemar_etl.py
[2024-04-13T06:05:15.015+0000] {processor.py:183} INFO - Processing /opt/airflow/dags/verdemar_etl.py took 0.026 seconds
[2024-04-13T06:05:45.168+0000] {processor.py:161} INFO - Started process (PID=4092) to work on /opt/airflow/dags/verdemar_etl.py
[2024-04-13T06:05:45.170+0000] {processor.py:830} INFO - Processing file /opt/airflow/dags/verdemar_etl.py for tasks to queue
[2024-04-13T06:05:45.172+0000] {logging_mixin.py:188} INFO - [2024-04-13T06:05:45.171+0000] {dagbag.py:540} INFO - Filling up the DagBag from /opt/airflow/dags/verdemar_etl.py
[2024-04-13T06:05:45.184+0000] {logging_mixin.py:188} INFO - [2024-04-13T06:05:45.181+0000] {dagbag.py:350} ERROR - Failed to import: /opt/airflow/dags/verdemar_etl.py
Traceback (most recent call last):
  File "/home/airflow/.local/lib/python3.12/site-packages/airflow/models/dagbag.py", line 346, in parse
    loader.exec_module(new_module)
  File "<frozen importlib._bootstrap_external>", line 991, in exec_module
  File "<frozen importlib._bootstrap_external>", line 1129, in get_code
  File "<frozen importlib._bootstrap_external>", line 1059, in source_to_code
  File "<frozen importlib._bootstrap>", line 488, in _call_with_frames_removed
  File "/opt/airflow/dags/verdemar_etl.py", line 14
    input_file = File(
IndentationError: unexpected indent
[2024-04-13T06:05:45.186+0000] {processor.py:842} WARNING - No viable dags retrieved from /opt/airflow/dags/verdemar_etl.py
[2024-04-13T06:05:45.206+0000] {processor.py:183} INFO - Processing /opt/airflow/dags/verdemar_etl.py took 0.048 seconds
[2024-04-13T06:06:15.592+0000] {processor.py:161} INFO - Started process (PID=4152) to work on /opt/airflow/dags/verdemar_etl.py
[2024-04-13T06:06:15.593+0000] {processor.py:830} INFO - Processing file /opt/airflow/dags/verdemar_etl.py for tasks to queue
[2024-04-13T06:06:15.596+0000] {logging_mixin.py:188} INFO - [2024-04-13T06:06:15.596+0000] {dagbag.py:540} INFO - Filling up the DagBag from /opt/airflow/dags/verdemar_etl.py
[2024-04-13T06:06:15.602+0000] {logging_mixin.py:188} INFO - [2024-04-13T06:06:15.601+0000] {dagbag.py:350} ERROR - Failed to import: /opt/airflow/dags/verdemar_etl.py
Traceback (most recent call last):
  File "/home/airflow/.local/lib/python3.12/site-packages/airflow/models/dagbag.py", line 346, in parse
    loader.exec_module(new_module)
  File "<frozen importlib._bootstrap_external>", line 991, in exec_module
  File "<frozen importlib._bootstrap_external>", line 1129, in get_code
  File "<frozen importlib._bootstrap_external>", line 1059, in source_to_code
  File "<frozen importlib._bootstrap>", line 488, in _call_with_frames_removed
  File "/opt/airflow/dags/verdemar_etl.py", line 14
    input_file = File(
IndentationError: unexpected indent
[2024-04-13T06:06:15.602+0000] {processor.py:842} WARNING - No viable dags retrieved from /opt/airflow/dags/verdemar_etl.py
[2024-04-13T06:06:15.622+0000] {processor.py:183} INFO - Processing /opt/airflow/dags/verdemar_etl.py took 0.039 seconds
[2024-04-13T06:06:45.946+0000] {processor.py:161} INFO - Started process (PID=4212) to work on /opt/airflow/dags/verdemar_etl.py
[2024-04-13T06:06:45.946+0000] {processor.py:830} INFO - Processing file /opt/airflow/dags/verdemar_etl.py for tasks to queue
[2024-04-13T06:06:45.948+0000] {logging_mixin.py:188} INFO - [2024-04-13T06:06:45.948+0000] {dagbag.py:540} INFO - Filling up the DagBag from /opt/airflow/dags/verdemar_etl.py
[2024-04-13T06:06:45.956+0000] {logging_mixin.py:188} INFO - [2024-04-13T06:06:45.953+0000] {dagbag.py:350} ERROR - Failed to import: /opt/airflow/dags/verdemar_etl.py
Traceback (most recent call last):
  File "/home/airflow/.local/lib/python3.12/site-packages/airflow/models/dagbag.py", line 346, in parse
    loader.exec_module(new_module)
  File "<frozen importlib._bootstrap_external>", line 991, in exec_module
  File "<frozen importlib._bootstrap_external>", line 1129, in get_code
  File "<frozen importlib._bootstrap_external>", line 1059, in source_to_code
  File "<frozen importlib._bootstrap>", line 488, in _call_with_frames_removed
  File "/opt/airflow/dags/verdemar_etl.py", line 14
    input_file = File(
IndentationError: unexpected indent
[2024-04-13T06:06:45.957+0000] {processor.py:842} WARNING - No viable dags retrieved from /opt/airflow/dags/verdemar_etl.py
[2024-04-13T06:06:45.981+0000] {processor.py:183} INFO - Processing /opt/airflow/dags/verdemar_etl.py took 0.042 seconds
[2024-04-13T06:07:16.095+0000] {processor.py:161} INFO - Started process (PID=4272) to work on /opt/airflow/dags/verdemar_etl.py
[2024-04-13T06:07:16.097+0000] {processor.py:830} INFO - Processing file /opt/airflow/dags/verdemar_etl.py for tasks to queue
[2024-04-13T06:07:16.099+0000] {logging_mixin.py:188} INFO - [2024-04-13T06:07:16.099+0000] {dagbag.py:540} INFO - Filling up the DagBag from /opt/airflow/dags/verdemar_etl.py
[2024-04-13T06:07:16.106+0000] {logging_mixin.py:188} INFO - [2024-04-13T06:07:16.105+0000] {dagbag.py:350} ERROR - Failed to import: /opt/airflow/dags/verdemar_etl.py
Traceback (most recent call last):
  File "/home/airflow/.local/lib/python3.12/site-packages/airflow/models/dagbag.py", line 346, in parse
    loader.exec_module(new_module)
  File "<frozen importlib._bootstrap_external>", line 991, in exec_module
  File "<frozen importlib._bootstrap_external>", line 1129, in get_code
  File "<frozen importlib._bootstrap_external>", line 1059, in source_to_code
  File "<frozen importlib._bootstrap>", line 488, in _call_with_frames_removed
  File "/opt/airflow/dags/verdemar_etl.py", line 14
    input_file = File(
IndentationError: unexpected indent
[2024-04-13T06:07:16.107+0000] {processor.py:842} WARNING - No viable dags retrieved from /opt/airflow/dags/verdemar_etl.py
[2024-04-13T06:07:16.123+0000] {processor.py:183} INFO - Processing /opt/airflow/dags/verdemar_etl.py took 0.036 seconds
[2024-04-13T06:07:46.347+0000] {processor.py:161} INFO - Started process (PID=4332) to work on /opt/airflow/dags/verdemar_etl.py
[2024-04-13T06:07:46.349+0000] {processor.py:830} INFO - Processing file /opt/airflow/dags/verdemar_etl.py for tasks to queue
[2024-04-13T06:07:46.351+0000] {logging_mixin.py:188} INFO - [2024-04-13T06:07:46.351+0000] {dagbag.py:540} INFO - Filling up the DagBag from /opt/airflow/dags/verdemar_etl.py
[2024-04-13T06:07:46.358+0000] {logging_mixin.py:188} INFO - [2024-04-13T06:07:46.356+0000] {dagbag.py:350} ERROR - Failed to import: /opt/airflow/dags/verdemar_etl.py
Traceback (most recent call last):
  File "/home/airflow/.local/lib/python3.12/site-packages/airflow/models/dagbag.py", line 346, in parse
    loader.exec_module(new_module)
  File "<frozen importlib._bootstrap_external>", line 991, in exec_module
  File "<frozen importlib._bootstrap_external>", line 1129, in get_code
  File "<frozen importlib._bootstrap_external>", line 1059, in source_to_code
  File "<frozen importlib._bootstrap>", line 488, in _call_with_frames_removed
  File "/opt/airflow/dags/verdemar_etl.py", line 14
    input_file = File(
IndentationError: unexpected indent
[2024-04-13T06:07:46.359+0000] {processor.py:842} WARNING - No viable dags retrieved from /opt/airflow/dags/verdemar_etl.py
[2024-04-13T06:07:46.382+0000] {processor.py:183} INFO - Processing /opt/airflow/dags/verdemar_etl.py took 0.046 seconds
[2024-04-13T06:08:16.503+0000] {processor.py:161} INFO - Started process (PID=4392) to work on /opt/airflow/dags/verdemar_etl.py
[2024-04-13T06:08:16.504+0000] {processor.py:830} INFO - Processing file /opt/airflow/dags/verdemar_etl.py for tasks to queue
[2024-04-13T06:08:16.506+0000] {logging_mixin.py:188} INFO - [2024-04-13T06:08:16.505+0000] {dagbag.py:540} INFO - Filling up the DagBag from /opt/airflow/dags/verdemar_etl.py
[2024-04-13T06:08:16.510+0000] {logging_mixin.py:188} INFO - [2024-04-13T06:08:16.509+0000] {dagbag.py:350} ERROR - Failed to import: /opt/airflow/dags/verdemar_etl.py
Traceback (most recent call last):
  File "/home/airflow/.local/lib/python3.12/site-packages/airflow/models/dagbag.py", line 346, in parse
    loader.exec_module(new_module)
  File "<frozen importlib._bootstrap_external>", line 991, in exec_module
  File "<frozen importlib._bootstrap_external>", line 1129, in get_code
  File "<frozen importlib._bootstrap_external>", line 1059, in source_to_code
  File "<frozen importlib._bootstrap>", line 488, in _call_with_frames_removed
  File "/opt/airflow/dags/verdemar_etl.py", line 14
    input_file = File(
IndentationError: unexpected indent
[2024-04-13T06:08:16.510+0000] {processor.py:842} WARNING - No viable dags retrieved from /opt/airflow/dags/verdemar_etl.py
[2024-04-13T06:08:16.528+0000] {processor.py:183} INFO - Processing /opt/airflow/dags/verdemar_etl.py took 0.032 seconds
[2024-04-13T06:08:46.965+0000] {processor.py:161} INFO - Started process (PID=4452) to work on /opt/airflow/dags/verdemar_etl.py
[2024-04-13T06:08:46.967+0000] {processor.py:830} INFO - Processing file /opt/airflow/dags/verdemar_etl.py for tasks to queue
[2024-04-13T06:08:46.969+0000] {logging_mixin.py:188} INFO - [2024-04-13T06:08:46.968+0000] {dagbag.py:540} INFO - Filling up the DagBag from /opt/airflow/dags/verdemar_etl.py
[2024-04-13T06:08:46.976+0000] {logging_mixin.py:188} INFO - [2024-04-13T06:08:46.975+0000] {dagbag.py:350} ERROR - Failed to import: /opt/airflow/dags/verdemar_etl.py
Traceback (most recent call last):
  File "/home/airflow/.local/lib/python3.12/site-packages/airflow/models/dagbag.py", line 346, in parse
    loader.exec_module(new_module)
  File "<frozen importlib._bootstrap_external>", line 991, in exec_module
  File "<frozen importlib._bootstrap_external>", line 1129, in get_code
  File "<frozen importlib._bootstrap_external>", line 1059, in source_to_code
  File "<frozen importlib._bootstrap>", line 488, in _call_with_frames_removed
  File "/opt/airflow/dags/verdemar_etl.py", line 14
    input_file = File(
IndentationError: unexpected indent
[2024-04-13T06:08:46.977+0000] {processor.py:842} WARNING - No viable dags retrieved from /opt/airflow/dags/verdemar_etl.py
[2024-04-13T06:08:46.996+0000] {processor.py:183} INFO - Processing /opt/airflow/dags/verdemar_etl.py took 0.039 seconds
[2024-04-13T06:09:17.421+0000] {processor.py:161} INFO - Started process (PID=4512) to work on /opt/airflow/dags/verdemar_etl.py
[2024-04-13T06:09:17.422+0000] {processor.py:830} INFO - Processing file /opt/airflow/dags/verdemar_etl.py for tasks to queue
[2024-04-13T06:09:17.424+0000] {logging_mixin.py:188} INFO - [2024-04-13T06:09:17.424+0000] {dagbag.py:540} INFO - Filling up the DagBag from /opt/airflow/dags/verdemar_etl.py
[2024-04-13T06:09:17.430+0000] {logging_mixin.py:188} INFO - [2024-04-13T06:09:17.429+0000] {dagbag.py:350} ERROR - Failed to import: /opt/airflow/dags/verdemar_etl.py
Traceback (most recent call last):
  File "/home/airflow/.local/lib/python3.12/site-packages/airflow/models/dagbag.py", line 346, in parse
    loader.exec_module(new_module)
  File "<frozen importlib._bootstrap_external>", line 991, in exec_module
  File "<frozen importlib._bootstrap_external>", line 1129, in get_code
  File "<frozen importlib._bootstrap_external>", line 1059, in source_to_code
  File "<frozen importlib._bootstrap>", line 488, in _call_with_frames_removed
  File "/opt/airflow/dags/verdemar_etl.py", line 14
    input_file = File(
IndentationError: unexpected indent
[2024-04-13T06:09:17.431+0000] {processor.py:842} WARNING - No viable dags retrieved from /opt/airflow/dags/verdemar_etl.py
[2024-04-13T06:09:17.447+0000] {processor.py:183} INFO - Processing /opt/airflow/dags/verdemar_etl.py took 0.033 seconds
[2024-04-13T06:09:47.630+0000] {processor.py:161} INFO - Started process (PID=4572) to work on /opt/airflow/dags/verdemar_etl.py
[2024-04-13T06:09:47.632+0000] {processor.py:830} INFO - Processing file /opt/airflow/dags/verdemar_etl.py for tasks to queue
[2024-04-13T06:09:47.634+0000] {logging_mixin.py:188} INFO - [2024-04-13T06:09:47.634+0000] {dagbag.py:540} INFO - Filling up the DagBag from /opt/airflow/dags/verdemar_etl.py
[2024-04-13T06:09:47.641+0000] {logging_mixin.py:188} INFO - [2024-04-13T06:09:47.640+0000] {dagbag.py:350} ERROR - Failed to import: /opt/airflow/dags/verdemar_etl.py
Traceback (most recent call last):
  File "/home/airflow/.local/lib/python3.12/site-packages/airflow/models/dagbag.py", line 346, in parse
    loader.exec_module(new_module)
  File "<frozen importlib._bootstrap_external>", line 991, in exec_module
  File "<frozen importlib._bootstrap_external>", line 1129, in get_code
  File "<frozen importlib._bootstrap_external>", line 1059, in source_to_code
  File "<frozen importlib._bootstrap>", line 488, in _call_with_frames_removed
  File "/opt/airflow/dags/verdemar_etl.py", line 14
    input_file = File(
IndentationError: unexpected indent
[2024-04-13T06:09:47.642+0000] {processor.py:842} WARNING - No viable dags retrieved from /opt/airflow/dags/verdemar_etl.py
[2024-04-13T06:09:47.662+0000] {processor.py:183} INFO - Processing /opt/airflow/dags/verdemar_etl.py took 0.041 seconds
[2024-04-13T06:10:18.071+0000] {processor.py:161} INFO - Started process (PID=4632) to work on /opt/airflow/dags/verdemar_etl.py
[2024-04-13T06:10:18.072+0000] {processor.py:830} INFO - Processing file /opt/airflow/dags/verdemar_etl.py for tasks to queue
[2024-04-13T06:10:18.075+0000] {logging_mixin.py:188} INFO - [2024-04-13T06:10:18.074+0000] {dagbag.py:540} INFO - Filling up the DagBag from /opt/airflow/dags/verdemar_etl.py
[2024-04-13T06:10:18.082+0000] {logging_mixin.py:188} INFO - [2024-04-13T06:10:18.081+0000] {dagbag.py:350} ERROR - Failed to import: /opt/airflow/dags/verdemar_etl.py
Traceback (most recent call last):
  File "/home/airflow/.local/lib/python3.12/site-packages/airflow/models/dagbag.py", line 346, in parse
    loader.exec_module(new_module)
  File "<frozen importlib._bootstrap_external>", line 991, in exec_module
  File "<frozen importlib._bootstrap_external>", line 1129, in get_code
  File "<frozen importlib._bootstrap_external>", line 1059, in source_to_code
  File "<frozen importlib._bootstrap>", line 488, in _call_with_frames_removed
  File "/opt/airflow/dags/verdemar_etl.py", line 14
    input_file = File(
IndentationError: unexpected indent
[2024-04-13T06:10:18.082+0000] {processor.py:842} WARNING - No viable dags retrieved from /opt/airflow/dags/verdemar_etl.py
[2024-04-13T06:10:18.099+0000] {processor.py:183} INFO - Processing /opt/airflow/dags/verdemar_etl.py took 0.037 seconds
[2024-04-13T06:10:48.686+0000] {processor.py:161} INFO - Started process (PID=4692) to work on /opt/airflow/dags/verdemar_etl.py
[2024-04-13T06:10:48.687+0000] {processor.py:830} INFO - Processing file /opt/airflow/dags/verdemar_etl.py for tasks to queue
[2024-04-13T06:10:48.689+0000] {logging_mixin.py:188} INFO - [2024-04-13T06:10:48.689+0000] {dagbag.py:540} INFO - Filling up the DagBag from /opt/airflow/dags/verdemar_etl.py
[2024-04-13T06:10:48.694+0000] {logging_mixin.py:188} INFO - [2024-04-13T06:10:48.693+0000] {dagbag.py:350} ERROR - Failed to import: /opt/airflow/dags/verdemar_etl.py
Traceback (most recent call last):
  File "/home/airflow/.local/lib/python3.12/site-packages/airflow/models/dagbag.py", line 346, in parse
    loader.exec_module(new_module)
  File "<frozen importlib._bootstrap_external>", line 991, in exec_module
  File "<frozen importlib._bootstrap_external>", line 1129, in get_code
  File "<frozen importlib._bootstrap_external>", line 1059, in source_to_code
  File "<frozen importlib._bootstrap>", line 488, in _call_with_frames_removed
  File "/opt/airflow/dags/verdemar_etl.py", line 14
    input_file = File(
IndentationError: unexpected indent
[2024-04-13T06:10:48.695+0000] {processor.py:842} WARNING - No viable dags retrieved from /opt/airflow/dags/verdemar_etl.py
[2024-04-13T06:10:48.724+0000] {processor.py:183} INFO - Processing /opt/airflow/dags/verdemar_etl.py took 0.048 seconds
[2024-04-13T06:11:19.423+0000] {processor.py:161} INFO - Started process (PID=4752) to work on /opt/airflow/dags/verdemar_etl.py
[2024-04-13T06:11:19.424+0000] {processor.py:830} INFO - Processing file /opt/airflow/dags/verdemar_etl.py for tasks to queue
[2024-04-13T06:11:19.426+0000] {logging_mixin.py:188} INFO - [2024-04-13T06:11:19.426+0000] {dagbag.py:540} INFO - Filling up the DagBag from /opt/airflow/dags/verdemar_etl.py
[2024-04-13T06:11:19.433+0000] {logging_mixin.py:188} INFO - [2024-04-13T06:11:19.431+0000] {dagbag.py:350} ERROR - Failed to import: /opt/airflow/dags/verdemar_etl.py
Traceback (most recent call last):
  File "/home/airflow/.local/lib/python3.12/site-packages/airflow/models/dagbag.py", line 346, in parse
    loader.exec_module(new_module)
  File "<frozen importlib._bootstrap_external>", line 991, in exec_module
  File "<frozen importlib._bootstrap_external>", line 1129, in get_code
  File "<frozen importlib._bootstrap_external>", line 1059, in source_to_code
  File "<frozen importlib._bootstrap>", line 488, in _call_with_frames_removed
  File "/opt/airflow/dags/verdemar_etl.py", line 14
    input_file = File(
IndentationError: unexpected indent
[2024-04-13T06:11:19.434+0000] {processor.py:842} WARNING - No viable dags retrieved from /opt/airflow/dags/verdemar_etl.py
[2024-04-13T06:11:19.457+0000] {processor.py:183} INFO - Processing /opt/airflow/dags/verdemar_etl.py took 0.046 seconds
