[2024-04-14T19:09:25.242+0000] {local_task_job_runner.py:120} INFO - ::group::Pre task execution logs
[2024-04-14T19:09:25.342+0000] {taskinstance.py:2073} INFO - Dependencies all met for dep_context=non-requeueable deps ti=<TaskInstance: upload_csv_to_s3.generate_and_upload_csv manual__2024-04-14T19:09:19.630114+00:00 [queued]>
[2024-04-14T19:09:25.368+0000] {taskinstance.py:2073} INFO - Dependencies all met for dep_context=requeueable deps ti=<TaskInstance: upload_csv_to_s3.generate_and_upload_csv manual__2024-04-14T19:09:19.630114+00:00 [queued]>
[2024-04-14T19:09:25.371+0000] {taskinstance.py:2303} INFO - Starting attempt 1 of 1
[2024-04-14T19:09:25.438+0000] {taskinstance.py:2327} INFO - Executing <Task(PythonOperator): generate_and_upload_csv> on 2024-04-14 19:09:19.630114+00:00
[2024-04-14T19:09:25.529+0000] {warnings.py:110} WARNING - /home/***/.local/lib/python3.12/site-packages/***/task/task_runner/standard_task_runner.py:61: DeprecationWarning: This process (pid=2660) is multi-threaded, use of fork() may lead to deadlocks in the child.
  pid = os.fork()

[2024-04-14T19:09:25.534+0000] {standard_task_runner.py:63} INFO - Started process 2662 to run task
[2024-04-14T19:09:25.541+0000] {standard_task_runner.py:90} INFO - Running: ['***', 'tasks', 'run', 'upload_csv_to_s3', 'generate_and_upload_csv', 'manual__2024-04-14T19:09:19.630114+00:00', '--job-id', '25', '--raw', '--subdir', 'DAGS_FOLDER/test_dag.py', '--cfg-path', '/tmp/tmp7werqdmi']
[2024-04-14T19:09:25.547+0000] {standard_task_runner.py:91} INFO - Job 25: Subtask generate_and_upload_csv
[2024-04-14T19:09:25.764+0000] {task_command.py:426} INFO - Running <TaskInstance: upload_csv_to_s3.generate_and_upload_csv manual__2024-04-14T19:09:19.630114+00:00 [running]> on host 514aa00dce91
[2024-04-14T19:09:25.887+0000] {taskinstance.py:2644} INFO - Exporting env vars: AIRFLOW_CTX_DAG_OWNER='***' AIRFLOW_CTX_DAG_ID='upload_csv_to_s3' AIRFLOW_CTX_TASK_ID='generate_and_upload_csv' AIRFLOW_CTX_EXECUTION_DATE='2024-04-14T19:09:19.630114+00:00' AIRFLOW_CTX_TRY_NUMBER='1' AIRFLOW_CTX_DAG_RUN_ID='manual__2024-04-14T19:09:19.630114+00:00'
[2024-04-14T19:09:25.892+0000] {taskinstance.py:430} INFO - ::endgroup::
[2024-04-14T19:09:26.884+0000] {logging_mixin.py:188} INFO - []
[2024-04-14T19:09:26.888+0000] {logging_mixin.py:188} INFO - Processing section: 16
[2024-04-14T19:09:29.022+0000] {base.py:84} INFO - Using connection ID 'aws_default' for task execution.
[2024-04-14T19:09:29.024+0000] {connection_wrapper.py:384} INFO - AWS Connection (conn_id='aws_default', conn_type='aws') credentials retrieved from login and password.
[2024-04-14T19:09:29.932+0000] {connection.py:547} WARNING - Certificate did not match expected hostname: verdemar-dataset.s3.s3.amazonaws.com. Certificate: {'subject': ((('commonName', '*.s3.amazonaws.com'),),), 'issuer': ((('countryName', 'US'),), (('organizationName', 'Amazon'),), (('commonName', 'Amazon RSA 2048 M01'),)), 'version': 3, 'serialNumber': '0B6D5022ACE696556FCC0827EBA0C09A', 'notBefore': 'Oct 10 00:00:00 2023 GMT', 'notAfter': 'Jul  3 23:59:59 2024 GMT', 'subjectAltName': (('DNS', '*.s3.amazonaws.com'), ('DNS', 's3.amazonaws.com')), 'OCSP': ('http://ocsp.r2m01.amazontrust.com',), 'caIssuers': ('http://crt.r2m01.amazontrust.com/r2m01.cer',), 'crlDistributionPoints': ('http://crl.r2m01.amazontrust.com/r2m01.crl',)}
[2024-04-14T19:09:30.882+0000] {connection.py:547} WARNING - Certificate did not match expected hostname: verdemar-dataset.s3.s3.amazonaws.com. Certificate: {'subject': ((('commonName', '*.s3.amazonaws.com'),),), 'issuer': ((('countryName', 'US'),), (('organizationName', 'Amazon'),), (('commonName', 'Amazon RSA 2048 M01'),)), 'version': 3, 'serialNumber': '0B6D5022ACE696556FCC0827EBA0C09A', 'notBefore': 'Oct 10 00:00:00 2023 GMT', 'notAfter': 'Jul  3 23:59:59 2024 GMT', 'subjectAltName': (('DNS', '*.s3.amazonaws.com'), ('DNS', 's3.amazonaws.com')), 'OCSP': ('http://ocsp.r2m01.amazontrust.com',), 'caIssuers': ('http://crt.r2m01.amazontrust.com/r2m01.cer',), 'crlDistributionPoints': ('http://crl.r2m01.amazontrust.com/r2m01.crl',)}
[2024-04-14T19:09:32.847+0000] {connection.py:547} WARNING - Certificate did not match expected hostname: verdemar-dataset.s3.s3.amazonaws.com. Certificate: {'subject': ((('commonName', '*.s3.amazonaws.com'),),), 'issuer': ((('countryName', 'US'),), (('organizationName', 'Amazon'),), (('commonName', 'Amazon RSA 2048 M01'),)), 'version': 3, 'serialNumber': '0B6D5022ACE696556FCC0827EBA0C09A', 'notBefore': 'Oct 10 00:00:00 2023 GMT', 'notAfter': 'Jul  3 23:59:59 2024 GMT', 'subjectAltName': (('DNS', '*.s3.amazonaws.com'), ('DNS', 's3.amazonaws.com')), 'OCSP': ('http://ocsp.r2m01.amazontrust.com',), 'caIssuers': ('http://crt.r2m01.amazontrust.com/r2m01.cer',), 'crlDistributionPoints': ('http://crl.r2m01.amazontrust.com/r2m01.crl',)}
[2024-04-14T19:09:34.316+0000] {connection.py:547} WARNING - Certificate did not match expected hostname: verdemar-dataset.s3.s3.amazonaws.com. Certificate: {'subject': ((('commonName', '*.s3.amazonaws.com'),),), 'issuer': ((('countryName', 'US'),), (('organizationName', 'Amazon'),), (('commonName', 'Amazon RSA 2048 M01'),)), 'version': 3, 'serialNumber': '0B6D5022ACE696556FCC0827EBA0C09A', 'notBefore': 'Oct 10 00:00:00 2023 GMT', 'notAfter': 'Jul  3 23:59:59 2024 GMT', 'subjectAltName': (('DNS', '*.s3.amazonaws.com'), ('DNS', 's3.amazonaws.com')), 'OCSP': ('http://ocsp.r2m01.amazontrust.com',), 'caIssuers': ('http://crt.r2m01.amazontrust.com/r2m01.cer',), 'crlDistributionPoints': ('http://crl.r2m01.amazontrust.com/r2m01.crl',)}
[2024-04-14T19:09:37.091+0000] {connection.py:547} WARNING - Certificate did not match expected hostname: verdemar-dataset.s3.s3.amazonaws.com. Certificate: {'subject': ((('commonName', '*.s3.amazonaws.com'),),), 'issuer': ((('countryName', 'US'),), (('organizationName', 'Amazon'),), (('commonName', 'Amazon RSA 2048 M01'),)), 'version': 3, 'serialNumber': '0B6D5022ACE696556FCC0827EBA0C09A', 'notBefore': 'Oct 10 00:00:00 2023 GMT', 'notAfter': 'Jul  3 23:59:59 2024 GMT', 'subjectAltName': (('DNS', '*.s3.amazonaws.com'), ('DNS', 's3.amazonaws.com')), 'OCSP': ('http://ocsp.r2m01.amazontrust.com',), 'caIssuers': ('http://crt.r2m01.amazontrust.com/r2m01.cer',), 'crlDistributionPoints': ('http://crl.r2m01.amazontrust.com/r2m01.crl',)}
[2024-04-14T19:09:37.094+0000] {taskinstance.py:441} INFO - ::group::Post task execution logs
[2024-04-14T19:09:37.096+0000] {taskinstance.py:2890} ERROR - Task failed with exception
Traceback (most recent call last):
  File "/home/airflow/.local/lib/python3.12/site-packages/urllib3/connectionpool.py", line 715, in urlopen
    httplib_response = self._make_request(
                       ^^^^^^^^^^^^^^^^^^^
  File "/home/airflow/.local/lib/python3.12/site-packages/urllib3/connectionpool.py", line 404, in _make_request
    self._validate_conn(conn)
  File "/home/airflow/.local/lib/python3.12/site-packages/urllib3/connectionpool.py", line 1058, in _validate_conn
    conn.connect()
  File "/home/airflow/.local/lib/python3.12/site-packages/urllib3/connection.py", line 472, in connect
    _match_hostname(cert, self.assert_hostname or server_hostname)
  File "/home/airflow/.local/lib/python3.12/site-packages/urllib3/connection.py", line 545, in _match_hostname
    match_hostname(cert, asserted_hostname)
  File "/home/airflow/.local/lib/python3.12/site-packages/urllib3/util/ssl_match_hostname.py", line 150, in match_hostname
    raise CertificateError(
urllib3.util.ssl_match_hostname.CertificateError: hostname 'verdemar-dataset.s3.s3.amazonaws.com' doesn't match either of '*.s3.amazonaws.com', 's3.amazonaws.com'

During handling of the above exception, another exception occurred:

Traceback (most recent call last):
  File "/home/airflow/.local/lib/python3.12/site-packages/botocore/httpsession.py", line 464, in send
    urllib_response = conn.urlopen(
                      ^^^^^^^^^^^^^
  File "/home/airflow/.local/lib/python3.12/site-packages/urllib3/connectionpool.py", line 799, in urlopen
    retries = retries.increment(
              ^^^^^^^^^^^^^^^^^^
  File "/home/airflow/.local/lib/python3.12/site-packages/urllib3/util/retry.py", line 525, in increment
    raise six.reraise(type(error), error, _stacktrace)
          ^^^^^^^^^^^^^^^^^^^^^^^^^^^^^^^^^^^^^^^^^^^^
  File "/home/airflow/.local/lib/python3.12/site-packages/urllib3/packages/six.py", line 769, in reraise
    raise value.with_traceback(tb)
  File "/home/airflow/.local/lib/python3.12/site-packages/urllib3/connectionpool.py", line 715, in urlopen
    httplib_response = self._make_request(
                       ^^^^^^^^^^^^^^^^^^^
  File "/home/airflow/.local/lib/python3.12/site-packages/urllib3/connectionpool.py", line 404, in _make_request
    self._validate_conn(conn)
  File "/home/airflow/.local/lib/python3.12/site-packages/urllib3/connectionpool.py", line 1058, in _validate_conn
    conn.connect()
  File "/home/airflow/.local/lib/python3.12/site-packages/urllib3/connection.py", line 472, in connect
    _match_hostname(cert, self.assert_hostname or server_hostname)
  File "/home/airflow/.local/lib/python3.12/site-packages/urllib3/connection.py", line 545, in _match_hostname
    match_hostname(cert, asserted_hostname)
  File "/home/airflow/.local/lib/python3.12/site-packages/urllib3/util/ssl_match_hostname.py", line 150, in match_hostname
    raise CertificateError(
urllib3.exceptions.SSLError: hostname 'verdemar-dataset.s3.s3.amazonaws.com' doesn't match either of '*.s3.amazonaws.com', 's3.amazonaws.com'

During handling of the above exception, another exception occurred:

Traceback (most recent call last):
  File "/home/airflow/.local/lib/python3.12/site-packages/airflow/models/taskinstance.py", line 465, in _execute_task
    result = _execute_callable(context=context, **execute_callable_kwargs)
             ^^^^^^^^^^^^^^^^^^^^^^^^^^^^^^^^^^^^^^^^^^^^^^^^^^^^^^^^^^^^^
  File "/home/airflow/.local/lib/python3.12/site-packages/airflow/models/taskinstance.py", line 432, in _execute_callable
    return execute_callable(context=context, **execute_callable_kwargs)
           ^^^^^^^^^^^^^^^^^^^^^^^^^^^^^^^^^^^^^^^^^^^^^^^^^^^^^^^^^^^^
  File "/home/airflow/.local/lib/python3.12/site-packages/airflow/models/baseoperator.py", line 400, in wrapper
    return func(self, *args, **kwargs)
           ^^^^^^^^^^^^^^^^^^^^^^^^^^^
  File "/home/airflow/.local/lib/python3.12/site-packages/airflow/operators/python.py", line 235, in execute
    return_value = self.execute_callable()
                   ^^^^^^^^^^^^^^^^^^^^^^^
  File "/home/airflow/.local/lib/python3.12/site-packages/airflow/operators/python.py", line 252, in execute_callable
    return self.python_callable(*self.op_args, **self.op_kwargs)
           ^^^^^^^^^^^^^^^^^^^^^^^^^^^^^^^^^^^^^^^^^^^^^^^^^^^^^
  File "/opt/airflow/dags/test_dag.py", line 83, in run_etl_process
    s3_client.put_object(Bucket=bucket_name, Key=file_key, Body=csv_buffer.getvalue())
  File "/home/airflow/.local/lib/python3.12/site-packages/botocore/client.py", line 553, in _api_call
    return self._make_api_call(operation_name, kwargs)
           ^^^^^^^^^^^^^^^^^^^^^^^^^^^^^^^^^^^^^^^^^^^
  File "/home/airflow/.local/lib/python3.12/site-packages/botocore/client.py", line 989, in _make_api_call
    http, parsed_response = self._make_request(
                            ^^^^^^^^^^^^^^^^^^^
  File "/home/airflow/.local/lib/python3.12/site-packages/botocore/client.py", line 1015, in _make_request
    return self._endpoint.make_request(operation_model, request_dict)
           ^^^^^^^^^^^^^^^^^^^^^^^^^^^^^^^^^^^^^^^^^^^^^^^^^^^^^^^^^^
  File "/home/airflow/.local/lib/python3.12/site-packages/botocore/endpoint.py", line 119, in make_request
    return self._send_request(request_dict, operation_model)
           ^^^^^^^^^^^^^^^^^^^^^^^^^^^^^^^^^^^^^^^^^^^^^^^^^
  File "/home/airflow/.local/lib/python3.12/site-packages/botocore/endpoint.py", line 202, in _send_request
    while self._needs_retry(
          ^^^^^^^^^^^^^^^^^^
  File "/home/airflow/.local/lib/python3.12/site-packages/botocore/endpoint.py", line 354, in _needs_retry
    responses = self._event_emitter.emit(
                ^^^^^^^^^^^^^^^^^^^^^^^^^
  File "/home/airflow/.local/lib/python3.12/site-packages/botocore/hooks.py", line 412, in emit
    return self._emitter.emit(aliased_event_name, **kwargs)
           ^^^^^^^^^^^^^^^^^^^^^^^^^^^^^^^^^^^^^^^^^^^^^^^^
  File "/home/airflow/.local/lib/python3.12/site-packages/botocore/hooks.py", line 256, in emit
    return self._emit(event_name, kwargs)
           ^^^^^^^^^^^^^^^^^^^^^^^^^^^^^^
  File "/home/airflow/.local/lib/python3.12/site-packages/botocore/hooks.py", line 239, in _emit
    response = handler(**kwargs)
               ^^^^^^^^^^^^^^^^^
  File "/home/airflow/.local/lib/python3.12/site-packages/botocore/retryhandler.py", line 207, in __call__
    if self._checker(**checker_kwargs):
       ^^^^^^^^^^^^^^^^^^^^^^^^^^^^^^^
  File "/home/airflow/.local/lib/python3.12/site-packages/botocore/retryhandler.py", line 284, in __call__
    should_retry = self._should_retry(
                   ^^^^^^^^^^^^^^^^^^^
  File "/home/airflow/.local/lib/python3.12/site-packages/botocore/retryhandler.py", line 320, in _should_retry
    return self._checker(attempt_number, response, caught_exception)
           ^^^^^^^^^^^^^^^^^^^^^^^^^^^^^^^^^^^^^^^^^^^^^^^^^^^^^^^^^
  File "/home/airflow/.local/lib/python3.12/site-packages/botocore/retryhandler.py", line 363, in __call__
    checker_response = checker(
                       ^^^^^^^^
  File "/home/airflow/.local/lib/python3.12/site-packages/botocore/retryhandler.py", line 247, in __call__
    return self._check_caught_exception(
           ^^^^^^^^^^^^^^^^^^^^^^^^^^^^^
  File "/home/airflow/.local/lib/python3.12/site-packages/botocore/retryhandler.py", line 416, in _check_caught_exception
    raise caught_exception
  File "/home/airflow/.local/lib/python3.12/site-packages/botocore/endpoint.py", line 281, in _do_get_response
    http_response = self._send(request)
                    ^^^^^^^^^^^^^^^^^^^
  File "/home/airflow/.local/lib/python3.12/site-packages/botocore/endpoint.py", line 377, in _send
    return self.http_session.send(request)
           ^^^^^^^^^^^^^^^^^^^^^^^^^^^^^^^
  File "/home/airflow/.local/lib/python3.12/site-packages/botocore/httpsession.py", line 491, in send
    raise SSLError(endpoint_url=request.url, error=e)
botocore.exceptions.SSLError: SSL validation failed for https://verdemar-dataset.s3.s3.amazonaws.com/products_20240414.csv hostname 'verdemar-dataset.s3.s3.amazonaws.com' doesn't match either of '*.s3.amazonaws.com', 's3.amazonaws.com'
[2024-04-14T19:09:37.129+0000] {taskinstance.py:1205} INFO - Marking task as FAILED. dag_id=upload_csv_to_s3, task_id=generate_and_upload_csv, execution_date=20240414T190919, start_date=20240414T190925, end_date=20240414T190937
[2024-04-14T19:09:37.143+0000] {standard_task_runner.py:110} ERROR - Failed to execute job 25 for task generate_and_upload_csv (SSL validation failed for https://verdemar-dataset.s3.s3.amazonaws.com/products_20240414.csv hostname 'verdemar-dataset.s3.s3.amazonaws.com' doesn't match either of '*.s3.amazonaws.com', 's3.amazonaws.com'; 2662)
[2024-04-14T19:09:37.177+0000] {local_task_job_runner.py:240} INFO - Task exited with return code 1
[2024-04-14T19:09:37.211+0000] {taskinstance.py:3482} INFO - 0 downstream tasks scheduled from follow-on schedule check
[2024-04-14T19:09:37.212+0000] {local_task_job_runner.py:222} INFO - ::endgroup::
